Workbook

Sheet Apr-Nov 2025
A1: Sn | B1: ='[1]CSC Wise Data'!A1 -> SR | C1: ='[1]CSC Wise Data'!B1 -> State | D1: ='[1]CSC Wise Data'!C1 -> CSC Name | E1: ='[1]CSC Wise Data'!E1 -> District | F1: ='[1]CSC Wise Data'!G1 -> Month | G1: Registration | J1: ICTC Linkage Loss | M1: Newly Initiated on-ART Cascade | S1: MIS Cascade | V1: LFU Cascade | Y1: CD4<200 Cascade | AB1: CD4<200 testing Cascade | AE1: PLHIV overdue for VL test Cascade | AH1: PLHIV on 3rd line ART due for VL | AK1: PLHIV with unsuppressed VL underwent repeat VL | AN1: Index Testing Cascade | AZ1: Discordant Couple Cascade | BC1: Newly HIV +ve PPW Cascade | BF1: PPW due for 32-36wk VL | BI1: EID Follow-up | BU1: ART linkage of +ve infants/children | BX1: TB Screening Cascade | CA1: FU for HIV TB co-infection | CD1: HIV-NCD Cascade
G2: New PLHIV Registered with ARTC "LL" received | H2: New client reg with CSC | I2: % of registration | J2: clients yet to linked with ARTC "LL" received | K2: definite outcome | L2: % of definite outcome | M2: NI "LL" received from ARTC | N2: NI clients contacted | O2: % of definite outcome | P2: NI clients "LL" received 7mnth ago | Q2: NI clients retainted on Tx at 7th mnth | R2: % of definite outcome | S2: MIS clients received from ARTC | T2: definite outcome | U2: % of definite outcome | V2: LFU clients received from ARTC | W2: Definite outcome | X2: % of definite outcome | Y2: clients whose CD4<200 "LL" received | Z2: clients whose CD4<200-Contacted | AA2: % Contacted | AB2: CD4<200 Cascade "LL" received from 6month ago | AC2: clients whose CD4<200 undergone testing | AD2: % of Testing | AE2: VL test overdue clients "LL" received from ARTC | AF2: VL test overdue clients-Tested for VL | AG2: % of VL tested | AH2: 3rd line clients due for VL "LL" received | AI2: 3rd line clients due for VL-Tested for VL | AJ2: % of VL tested | AK2: unsuppressed clients "LL" received from ARTC | AL2: unsuppressed clients tested for VL | AM2: % of VL tested | AN2: FM eligible for HIV screening/testing | AO2: FM screened /tested for HIV | AP2: % of HIV Testing | AQ2: SP eligible for HIV screening/testing | AR2: SP screened /tested for HIV | AS2: % of HIV Testing | AT2: BC eligible for HIV screening/testing | AU2: BC screened /tested for HIV | AV2: % of HIV Testing | AW2: Total eligible for HIV screening/testing | AX2: screened /tested for HIV | AY2: % of HIV Testing | AZ2: DC due for repeat test | BA2: DC retested for HIV | BB2: % of HIV Testing | BC2: new PPW "LL" received | BD2: PPW initiated on ART | BE2: % of PPW initiated on ART | BF2: PPW due for 32-36wk VL "LL" rcvd | BG2: PPW due for 32-36wk VL-Tested for VL | BH2: % of VL Testing | BI2: HEI tested for 1st EID | BJ2: Tested for EID | BK2: % of EID testing | BL2: HEI tested for 2nd EID | BM2: Tested for EID | BN2: % of EID testing | BO2: HEI tested for 3rd EID | BP2: Tested for EID | BQ2: % of EID testing | BR2: HEI tested for 4th EID | BS2: Tested for EID | BT2: % of EID testing | BU2: Number of HEI found EID (+Ve) | BV2: Number of HEI linked with ART | BW2: % of ART Linkages | BX2: clients screened for TB 1st time | BY2: clients re-screened for TB | BZ2: % of TB Screening | CA2: HIV-TB clients "LL" received | CB2: HIV-TB clients-Adhere to ART & ATT | CC2: % of Adherence | CD2: HIV-NCD clients "LL" received | CE2: HIV-NCD clients contacted | CF2: % of HIV-NCD clients contacted
A3: 1 | B3: CHRI | C3: BR,WB,MG,TR, SK,NG,AS,AP | D3: 27 | F3: =F7 -> Apr-Dec'25 | G3: =SUMIF($B$7:$B$82,"CHRI",G7:G82) -> 14326 | H3: =SUMIF($B$7:$B$82,"CHRI",H7:H82) -> 14147 | I3: =H3/G3 -> 0.98750524 | J3: =SUMIF($B$7:$B$82,"CHRI",J7:J82) -> 6005 | K3: =SUMIF($B$7:$B$82,"CHRI",K7:K82) -> 5430 | L3: =K3/J3 -> 0.90424646 | M3: =SUMIF($B$7:$B$82,"CHRI",M7:M82) -> 13144 | N3: =SUMIF($B$7:$B$82,"CHRI",N7:N82) -> 12582 | O3: =N3/M3 -> 0.95724285 | P3: =SUMIF($B$7:$B$82,"CHRI",P7:P82) -> 10445 | Q3: =SUMIF($B$7:$B$82,"CHRI",Q7:Q82) -> 8884 | R3: =Q3/P3 -> 0.8505505 | S3: =SUMIF($B$7:$B$82,"CHRI",S7:S82) -> 64690 | T3: =SUMIF($B$7:$B$82,"CHRI",T7:T82) -> 47340 | U3: =T3/S3 -> 0.7317978 | V3: =SUMIF($B$7:$B$82,"CHRI",V7:V82) -> 28993 | W3: =SUMIF($B$7:$B$82,"CHRI",W7:W82) -> 14690 | X3: =W3/V3 -> 0.50667402 | Y3: =SUMIF($B$7:$B$82,"CHRI",Y7:Y82) -> 3965 | Z3: =SUMIF($B$7:$B$82,"CHRI",Z7:Z82) -> 2967 | AA3: =Z3/Y3 -> 0.7482976 | AB3: =SUMIF($B$7:$B$82,"CHRI",AB7:AB82) -> 2910 | AC3: =SUMIF($B$7:$B$82,"CHRI",AC7:AC82) -> 1203 | AD3: =AC3/AB3 -> 0.41340206 | AE3: =SUMIF($B$7:$B$82,"CHRI",AE7:AE82) -> 45771 | AF3: =SUMIF($B$7:$B$82,"CHRI",AF7:AF82) -> 36742 | AG3: =AF3/AE3 -> 0.80273536 | AH3: =SUMIF($B$7:$B$82,"CHRI",AH7:AH82) -> 51 | AI3: =SUMIF($B$7:$B$82,"CHRI",AI7:AI82) -> 15 | AJ3: =AI3/AH3 -> 0.29411765 | AK3: =SUMIF($B$7:$B$82,"CHRI",AK7:AK82) -> 4992 | AL3: =SUMIF($B$7:$B$82,"CHRI",AL7:AL82) -> 1965 | AM3: =AL3/AK3 -> 0.39362981 | AN3: =SUMIF($B$7:$B$82,"CHRI",AN7:AN82) -> 4989 | AO3: =SUMIF($B$7:$B$82,"CHRI",AO7:AO82) -> 4630 | AP3: =AO3/AN3 -> 0.92804169 | AQ3: =SUMIF($B$7:$B$82,"CHRI",AQ7:AQ82) -> 226 | AR3: =SUMIF($B$7:$B$82,"CHRI",AR7:AR82) -> 79 | AS3: =AR3/AQ3 -> 0.34955752 | AT3: =SUMIF($B$7:$B$82,"CHRI",AT7:AT82) -> 3629 | AU3: =SUMIF($B$7:$B$82,"CHRI",AU7:AU82) -> 3350 | AV3: =AU3/AT3 -> 0.92311932 | AW3: =AN3+AQ3+AT3 -> 8844 | AX3: =AO3+AR3+AU3 -> 8059 | AY3: =AX3/AW3 -> 0.91123926 | AZ3: =SUMIF($B$7:$B$82,"CHRI",AZ7:AZ82) -> 5721 | BA3: =SUMIF($B$7:$B$82,"CHRI",BA7:BA82) -> 2751 | BB3: =SUMIF($B$7:$B$82,"CHRI",BB7:BB82) -> 19.920498 | BC3: =SUMIF($B$7:$B$82,"CHRI",BC7:BC82) -> 419 | BD3: =SUMIF($B$7:$B$82,"CHRI",BD7:BD82) -> 485 | BE3: =SUMIF($B$7:$B$82,"CHRI",BE7:BE82) -> 26.65828 | BF3: =SUMIF($B$7:$B$82,"CHRI",BF7:BF82) -> 880 | BG3: =SUMIF($B$7:$B$82,"CHRI",BG7:BG82) -> 805 | ... CF3: =SUMIF($B$7:$B$82,"CHRI",CF7:CF82) -> 9.8315789
A4: 2 | B4: YRG | C4: DD,Raj,OD | D4: 23 | F4: =F8 -> Apr-Dec'25 | G4: =SUMIF($B$7:$B$82,"YRG Care",G7:G82) -> 8517 | H4: =SUMIF($B$7:$B$82,"YRG Care",H7:H82) -> 7360 | I4: =H4/G4 -> 0.86415404 | J4: =SUMIF($B$7:$B$82,"YRG Care",J7:J82) -> 182 | K4: =SUMIF($B$7:$B$82,"YRG Care",K7:K82) -> 72 | L4: =K4/J4 -> 0.3956044 | M4: =SUMIF($B$7:$B$82,"YRG Care",M7:M82) -> 7772 | N4: =SUMIF($B$7:$B$82,"YRG Care",N7:N82) -> 7596 | O4: =N4/M4 -> 0.97735461 | P4: =SUMIF($B$7:$B$82,"YRG Care",P7:P82) -> 6708 | Q4: =SUMIF($B$7:$B$82,"YRG Care",Q7:Q82) -> 5674 | R4: =Q4/P4 -> 0.84585569 | S4: =SUMIF($B$7:$B$82,"YRG Care",S7:S82) -> 44142 | T4: =SUMIF($B$7:$B$82,"YRG Care",T7:T82) -> 33612 | U4: =T4/S4 -> 0.76145168 | V4: =SUMIF($B$7:$B$82,"YRG Care",V7:V82) -> 18257 | W4: =SUMIF($B$7:$B$82,"YRG Care",W7:W82) -> 12727 | X4: =W4/V4 -> 0.69710248 | Y4: =SUMIF($B$7:$B$82,"YRG Care",Y7:Y82) -> 3612 | Z4: =SUMIF($B$7:$B$82,"YRG Care",Z7:Z82) -> 3416 | AA4: =Z4/Y4 -> 0.94573643 | AB4: =SUMIF($B$7:$B$82,"YRG Care",AB7:AB82) -> 2649 | AC4: =SUMIF($B$7:$B$82,"YRG Care",AC7:AC82) -> 1038 | AD4: =AC4/AB4 -> 0.39184598 | AE4: =SUMIF($B$7:$B$82,"YRG Care",AE7:AE82) -> 19554 | AF4: =SUMIF($B$7:$B$82,"YRG Care",AF7:AF82) -> 14870 | AG4: =AF4/AE4 -> 0.76045822 | AH4: =SUMIF($B$7:$B$82,"YRG Care",AH7:AH82) -> 215 | AI4: =SUMIF($B$7:$B$82,"YRG Care",AI7:AI82) -> 183 | AJ4: =AI4/AH4 -> 0.85116279 | AK4: =SUMIF($B$7:$B$82,"YRG Care",AK7:AK82) -> 3798 | AL4: =SUMIF($B$7:$B$82,"YRG Care",AL7:AL82) -> 1967 | AM4: =AL4/AK4 -> 0.51790416 | AN4: =SUMIF($B$7:$B$82,"YRG Care",AN7:AN82) -> 1171 | AO4: =SUMIF($B$7:$B$82,"YRG Care",AO7:AO82) -> 670 | AP4: =AO4/AN4 -> 0.57216055 | AQ4: =SUMIF($B$7:$B$82,"YRG Care",AQ7:AQ82) -> 121 | AR4: =SUMIF($B$7:$B$82,"YRG Care",AR7:AR82) -> 70 | AS4: =AR4/AQ4 -> 0.5785124 | AT4: =SUMIF($B$7:$B$82,"YRG Care",AT7:AT82) -> 871 | AU4: =SUMIF($B$7:$B$82,"YRG Care",AU7:AU82) -> 500 | AV4: =AU4/AT4 -> 0.57405281 | AW4: =AN4+AQ4+AT4 -> 2163 | AX4: =AO4+AR4+AU4 -> 1240 | AY4: =AX4/AW4 -> 0.57327785 | AZ4: =SUMIF($B$7:$B$82,"YRG Care",AZ7:AZ82) -> 638 | BA4: =SUMIF($B$7:$B$82,"YRG Care",BA7:BA82) -> 834 | BB4: =SUMIF($B$7:$B$82,"YRG Care",BB7:BB82) -> 25.810424 | BC4: =SUMIF($B$7:$B$82,"YRG Care",BC7:BC82) -> 77 | BD4: =SUMIF($B$7:$B$82,"YRG Care",BD7:BD82) -> 45 | BE4: =SUMIF($B$7:$B$82,"YRG Care",BE7:BE82) -> 9.1622807 | BF4: =SUMIF($B$7:$B$82,"YRG Care",BF7:BF82) -> 110 | BG4: =SUMIF($B$7:$B$82,"YRG Care",BG7:BG82) -> 99 | ... CF4: =SUMIF($B$7:$B$82,"YRG Care",CF7:CF82) -> 2.7563636
A5: 3 | B5: UPNP+ | C5: Uttar Pradesh | D5: 24 | F5: =F9 -> Apr-Dec'25 | G5: =SUMIF($B$7:$B$82,"UPNP+",G7:G82) -> 14225 | H5: =SUMIF($B$7:$B$82,"UPNP+",H7:H82) -> 12101 | I5: =H5/G5 -> 0.85068541 | J5: =SUMIF($B$7:$B$82,"UPNP+",J7:J82) -> 223 | K5: =SUMIF($B$7:$B$82,"UPNP+",K7:K82) -> 159 | L5: =K5/J5 -> 0.71300448 | M5: =SUMIF($B$7:$B$82,"UPNP+",M7:M82) -> 12808 | N5: =SUMIF($B$7:$B$82,"UPNP+",N7:N82) -> 12808 | O5: =N5/M5 -> 1 | P5: =SUMIF($B$7:$B$82,"UPNP+",P7:P82) -> 10676 | Q5: =SUMIF($B$7:$B$82,"UPNP+",Q7:Q82) -> 8958 | R5: =Q5/P5 -> 0.83907831 | S5: =SUMIF($B$7:$B$82,"UPNP+",S7:S82) -> 56355 | T5: =SUMIF($B$7:$B$82,"UPNP+",T7:T82) -> 45790 | U5: =T5/S5 -> 0.81252773 | V5: =SUMIF($B$7:$B$82,"UPNP+",V7:V82) -> 18100 | W5: =SUMIF($B$7:$B$82,"UPNP+",W7:W82) -> 13046 | X5: =W5/V5 -> 0.72077348 | Y5: =SUMIF($B$7:$B$82,"UPNP+",Y7:Y82) -> 5347 | Z5: =SUMIF($B$7:$B$82,"UPNP+",Z7:Z82) -> 5346 | AA5: =Z5/Y5 -> 0.99981298 | AB5: =SUMIF($B$7:$B$82,"UPNP+",AB7:AB82) -> 5281 | AC5: =SUMIF($B$7:$B$82,"UPNP+",AC7:AC82) -> 3844 | AD5: =AC5/AB5 -> 0.72789244 | AE5: =SUMIF($B$7:$B$82,"UPNP+",AE7:AE82) -> 23183 | AF5: =SUMIF($B$7:$B$82,"UPNP+",AF7:AF82) -> 19858 | AG5: =AF5/AE5 -> 0.85657594 | AH5: =SUMIF($B$7:$B$82,"UPNP+",AH7:AH82) -> 228 | AI5: =SUMIF($B$7:$B$82,"UPNP+",AI7:AI82) -> 209 | AJ5: =AI5/AH5 -> 0.91666667 | AK5: =SUMIF($B$7:$B$82,"UPNP+",AK7:AK82) -> 2555 | AL5: =SUMIF($B$7:$B$82,"UPNP+",AL7:AL82) -> 2152 | AM5: =AL5/AK5 -> 0.84227006 | AN5: =SUMIF($B$7:$B$82,"UPNP+",AN7:AN82) -> 2288 | AO5: =SUMIF($B$7:$B$82,"UPNP+",AO7:AO82) -> 2043 | AP5: =AO5/AN5 -> 0.89291958 | AQ5: =SUMIF($B$7:$B$82,"UPNP+",AQ7:AQ82) -> 32 | AR5: =SUMIF($B$7:$B$82,"UPNP+",AR7:AR82) -> 31 | AS5: =AR5/AQ5 -> 0.96875 | AT5: =SUMIF($B$7:$B$82,"UPNP+",AT7:AT82) -> 2163 | AU5: =SUMIF($B$7:$B$82,"UPNP+",AU7:AU82) -> 1951 | AV5: =AU5/AT5 -> 0.90198798 | AW5: =AN5+AQ5+AT5 -> 4483 | AX5: =AO5+AR5+AU5 -> 4025 | AY5: =AX5/AW5 -> 0.89783627 | AZ5: =SUMIF($B$7:$B$82,"UPNP+",AZ7:AZ82) -> 1806 | BA5: =SUMIF($B$7:$B$82,"UPNP+",BA7:BA82) -> 4210 | BB5: =SUMIF($B$7:$B$82,"UPNP+",BB7:BB82) -> 100.30075 | BC5: =SUMIF($B$7:$B$82,"UPNP+",BC7:BC82) -> 604 | BD5: =SUMIF($B$7:$B$82,"UPNP+",BD7:BD82) -> 604 | BE5: =SUMIF($B$7:$B$82,"UPNP+",BE7:BE82) -> 27 | BF5: =SUMIF($B$7:$B$82,"UPNP+",BF7:BF82) -> 788 | BG5: =SUMIF($B$7:$B$82,"UPNP+",BG7:BG82) -> 771 | ... CF5: =SUMIF($B$7:$B$82,"UPNP+",CF7:CF82) -> 13.728261
C6: Total | D6: =D5+D4+D3 -> 74 | G6: =G5+G4+G3 -> 37068 | H6: =H5+H4+H3 -> 33608 | I6: =H6/G6 -> 0.90665803 | J6: =J5+J4+J3 -> 6410 | K6: =K5+K4+K3 -> 5661 | L6: =K6/J6 -> 0.88315133 | M6: =M5+M4+M3 -> 33724 | N6: =N5+N4+N3 -> 32986 | O6: =N6/M6 -> 0.97811647 | P6: =P5+P4+P3 -> 27829 | Q6: =Q5+Q4+Q3 -> 23516 | R6: =Q6/P6 -> 0.84501779 | S6: =S5+S4+S3 -> 165187 | T6: =T5+T4+T3 -> 126742 | U6: =T6/S6 -> 0.76726377 | V6: =V5+V4+V3 -> 65350 | W6: =W5+W4+W3 -> 40463 | X6: =W6/V6 -> 0.61917368 | Y6: =Y5+Y4+Y3 -> 12924 | Z6: =Z5+Z4+Z3 -> 11729 | AA6: =Z6/Y6 -> 0.90753637 | AB6: =AB5+AB4+AB3 -> 10840 | AC6: =AC5+AC4+AC3 -> 6085 | AD6: =AC6/AB6 -> 0.56134686 | AE6: =AE5+AE4+AE3 -> 88508 | AF6: =AF5+AF4+AF3 -> 71470 | AG6: =AF6/AE6 -> 0.80749763 | AH6: =AH5+AH4+AH3 -> 494 | AI6: =AI5+AI4+AI3 -> 407 | AJ6: =AI6/AH6 -> 0.82388664 | AK6: =AK5+AK4+AK3 -> 11345 | AL6: =AL5+AL4+AL3 -> 6084 | AM6: =AL6/AK6 -> 0.53627149 | AN6: =AN5+AN4+AN3 -> 8448 | AO6: =AO5+AO4+AO3 -> 7343 | AP6: =AO6/AN6 -> 0.86919981 | AQ6: =AQ5+AQ4+AQ3 -> 379 | AR6: =AR5+AR4+AR3 -> 180 | AS6: =AR6/AQ6 -> 0.47493404 | AT6: =AT5+AT4+AT3 -> 6663 | AU6: =AU5+AU4+AU3 -> 5801 | AV6: =AU6/AT6 -> 0.87062885 | AW6: =AN6+AQ6+AT6 -> 15490 | AX6: =AO6+AR6+AU6 -> 13324 | AY6: =AX6/AW6 -> 0.86016785 | AZ6: =AZ5+AZ4+AZ3 -> 8165 | BA6: =BA5+BA4+BA3 -> 7795 | BB6: =IFERROR(BA6/AZ6,0) -> 0.95468463 | BC6: =BC5+BC4+BC3 -> 1100 | BD6: =BD5+BD4+BD3 -> 1134 | BE6: =IFERROR(BD6/BC6,0) -> 1.0309091 | BF6: =BF5+BF4+BF3 -> 1778 | BG6: =BG5+BG4+BG3 -> 1675 | BH6: =IFERROR(BG6/BF6,0) -> 0.94206974 | BI6: =BI5+BI4+BI3 -> 1594 | BJ6: =BJ5+BJ4+BJ3 -> 1509 | BK6: =IFERROR(BJ6/BI6,0) -> 0.94667503 | BL6: =BL5+BL4+BL3 -> 1208 | BM6: =BM5+BM4+BM3 -> 1088 | BN6: =IFERROR(BM6/BL6,0) -> 0.90066225 | BO6: =BO5+BO4+BO3 -> 1039 | BP6: =BP5+BP4+BP3 -> 901 | BQ6: =IFERROR(BP6/BO6,0) -> 0.86717998 | BR6: =BR5+BR4+BR3 -> 1072 | BS6: =BS5+BS4+BS3 -> 946 | BT6: =IFERROR(BS6/BR6,0) -> 0.88246269 | BU6: =BU5+BU4+BU3 -> 16 | BV6: =BV5+BV4+BV3 -> 15 | BW6: =IFERROR(BV6/BU6,0) -> 0.9375 | BX6: =BX5+BX4+BX3 -> 33608 | BY6: =BY5+BY4+BY3 -> 35388 | BZ6: =IFERROR(BY6/BX6,0) -> 1.0529636 | CA6: =CA5+CA4+CA3 -> 12395 | CB6: =CB5+CB4+CB3 -> 12512 | CC6: =IFERROR(CB6/CA6,0) -> 1.0094393 | CD6: =CD5+CD4+CD3 -> 1415 | CE6: =CE5+CE4+CE3 -> 1379 | CF6: =IFERROR(CE6/CD6,0) -> 0.9745583
A7: ='[2]Oct-Dec''25'!A7 -> 1 | B7: ='[2]Oct-Dec''25'!B7 -> CHRI | C7: ='[2]Oct-Dec''25'!C7 -> Arunachal Pradesh | D7: ='[2]Oct-Dec''25'!D7 -> ASSAM NETWORK OF POSITIVE PEOPLE(ANP+), DIBRUGARH | E7: ='[2]Oct-Dec''25'!E7 -> PAPUM PARE, NAMSAI | F7: Apr-Dec'25 | G7: ='[2]Oct-Dec''25'!H7+'[2]Apr-Sep''25'!H7 -> 298 | H7: ='[2]Oct-Dec''25'!I7+'[2]Apr-Sep''25'!I7 -> 223 | I7: =H7/G7 -> 0.74832215 | J7: ='[2]Oct-Dec''25'!K7+'[2]Apr-Sep''25'!K7 -> 529 | K7: ='[2]Oct-Dec''25'!L7+'[2]Apr-Sep''25'!L7 -> 529 | L7: =K7/J7 -> 1 | M7: ='[2]Oct-Dec''25'!N7+'[2]Apr-Sep''25'!N7 -> 288 | N7: ='[2]Oct-Dec''25'!O7+'[2]Apr-Sep''25'!O7 -> 288 | O7: =N7/M7 -> 1 | P7: ='[2]Oct-Dec''25'!Q7+'[2]Apr-Sep''25'!Q7 -> 127 | Q7: ='[2]Oct-Dec''25'!R7+'[2]Apr-Sep''25'!R7 -> 118 | R7: =Q7/P7 -> 0.92913386 | S7: ='[2]Oct-Dec''25'!T7+'[2]Apr-Sep''25'!T7 -> 1203 | T7: ='[2]Oct-Dec''25'!U7+'[2]Apr-Sep''25'!U7 -> 289 | U7: =T7/S7 -> 0.24023275 | V7: ='[2]Oct-Dec''25'!W7+'[2]Apr-Sep''25'!W7 -> 1086 | W7: ='[2]Oct-Dec''25'!Y7+'[2]Apr-Sep''25'!Y7 -> 476 | X7: =W7/V7 -> 0.43830571 | Y7: ='[2]Oct-Dec''25'!AA7+'[2]Apr-Sep''25'!AA7 -> 43 | Z7: ='[2]Oct-Dec''25'!AB7+'[2]Apr-Sep''25'!AB7 -> 37 | AA7: =Z7/Y7 -> 0.86046512 | AB7: ='[2]Oct-Dec''25'!AD7+'[2]Apr-Sep''25'!AD7 -> 0 | AC7: ='[2]Oct-Dec''25'!AE7+'[2]Apr-Sep''25'!AE7 -> 0 | AD7: =AC7/AB7 -> #DIV/0! | AE7: ='[2]Oct-Dec''25'!AJ7+'[2]Apr-Sep''25'!AJ7 -> 798 | AF7: ='[2]Oct-Dec''25'!AK7+'[2]Apr-Sep''25'!AK7 -> 338 | AG7: =AF7/AE7 -> 0.4235589 | AH7: ='[2]Oct-Dec''25'!AM7+'[2]Apr-Sep''25'!AM7 -> 0 | AI7: ='[2]Oct-Dec''25'!AN7+'[2]Apr-Sep''25'!AN7 -> 0 | AJ7: =AI7/AH7 -> #DIV/0! | AK7: ='[2]Oct-Dec''25'!AP7+'[2]Apr-Sep''25'!AP7 -> 78 | AL7: ='[2]Oct-Dec''25'!AQ7+'[2]Apr-Sep''25'!AQ7 -> 28 | AM7: =AL7/AK7 -> 0.35897436 | AN7: ='[2]Oct-Dec''25'!AS7+'[2]Apr-Sep''25'!AS7 -> 74 | AO7: ='[2]Oct-Dec''25'!AT7+'[2]Apr-Sep''25'!AT7 -> 71 | AP7: =AO7/AN7 -> 0.95945946 | AQ7: ='[2]Oct-Dec''25'!AV7+'[2]Apr-Sep''25'!AV7 -> 8 | AR7: ='[2]Oct-Dec''25'!AW7+'[2]Apr-Sep''25'!AW7 -> 8 | AS7: =AR7/AQ7 -> 1 | AT7: ='[2]Oct-Dec''25'!AY7+'[2]Apr-Sep''25'!AY7 -> 21 | AU7: ='[2]Oct-Dec''25'!AZ7+'[2]Apr-Sep''25'!AZ7 -> 21 | AV7: =AU7/AT7 -> 1 | AW7: =AN7+AQ7+AT7 -> 103 | AX7: =AO7+AR7+AU7 -> 100 | AY7: =AX7/AW7 -> 0.97087379 | AZ7: ='[2]Oct-Dec''25'!BB7+'[2]Apr-Sep''25'!BB7 -> 2 | BA7: ='[2]Oct-Dec''25'!BC7+'[2]Apr-Sep''25'!BC7 -> 2 | BB7: =IFERROR(BA7/AZ7,0) -> 1 | BC7: ='[2]Oct-Dec''25'!BE7+'[2]Apr-Sep''25'!BE7 -> 0 | BD7: ='[2]Oct-Dec''25'!BF7+'[2]Apr-Sep''25'!BF7 -> 0 | BE7: =IFERROR(BD7/BC7,0) -> 0 | BF7: ='[2]Oct-Dec''25'!BH7+'[2]Apr-Sep''25'!BH7 -> 5 | BG7: ='[2]Oct-Dec''25'!BI7+'[2]Apr-Sep''25'!BI7 -> 5 | BH7: =IFERROR(BG7/BF7,0) -> 1 | BI7: ='[2]Oct-Dec''25'!BK7+'[2]Apr-Sep''25'!BK7 -> 7 | BJ7: ='[2]Oct-Dec''25'!BL7+'[2]Apr-Sep''25'!BL7 -> 7 | BK7: =IFERROR(BJ7/BI7,0) -> 1 | BL7: ='[2]Oct-Dec''25'!BN7+'[2]Apr-Sep''25'!BN7 -> 0 | BM7: ='[2]Oct-Dec''25'!BO7+'[2]Apr-Sep''25'!BO7 -> 0 | BN7: =IFERROR(BM7/BL7,0) -> 0 | BO7: ='[2]Oct-Dec''25'!BQ7+'[2]Apr-Sep''25'!BQ7 -> 3 | BP7: ='[2]Oct-Dec''25'!BR7+'[2]Apr-Sep''25'!BR7 -> 3 | BQ7: =IFERROR(BP7/BO7,0) -> 1 | BR7: ='[2]Oct-Dec''25'!BT7+'[2]Apr-Sep''25'!BT7 -> 2 | BS7: ='[2]Oct-Dec''25'!BU7+'[2]Apr-Sep''25'!BU7 -> 2 | BT7: =IFERROR(BS7/BR7,0) -> 1 | BU7: ='[2]Oct-Dec''25'!BW7+'[2]Apr-Sep''25'!BW7 -> 0 | BV7: ='[2]Oct-Dec''25'!BX7+'[2]Apr-Sep''25'!BX7 -> 0 | BW7: =IFERROR(BV7/BU7,0) -> 0 | BX7: ='[2]Oct-Dec''25'!BZ7+'[2]Apr-Sep''25'!BZ7 -> 223 | BY7: ='[2]Oct-Dec''25'!CA7+'[2]Apr-Sep''25'!CA7 -> 201 | BZ7: =IFERROR(BY7/BX7,0) -> 0.90134529 | CA7: ='[2]Oct-Dec''25'!CC7+'[2]Apr-Sep''25'!CC7 -> 14 | CB7: ='[2]Oct-Dec''25'!CD7+'[2]Apr-Sep''25'!CD7 -> 11 | CC7: =IFERROR(CB7/CA7,0) -> 0.78571429 | CD7: ='[2]Oct-Dec''25'!CF7+'[2]Apr-Sep''25'!CF7 -> 5 | CE7: ='[2]Oct-Dec''25'!CG7+'[2]Apr-Sep''25'!CG7 -> 1 | CF7: =IFERROR(CE7/CD7,0) -> 0.2
A8: ='[2]Oct-Dec''25'!A8 -> 2 | B8: ='[2]Oct-Dec''25'!B8 -> CHRI | C8: ='[2]Oct-Dec''25'!C8 -> Assam | D8: ='[2]Oct-Dec''25'!D8 -> ASSAM NETWORK OF POSITIVE PEOPLE(ANP+), DIBRUGARH | E8: ='[2]Oct-Dec''25'!E8 -> DIBRUGARH | F8: Apr-Dec'25 | G8: ='[2]Oct-Dec''25'!H8+'[2]Apr-Sep''25'!H8 -> 600 | H8: ='[2]Oct-Dec''25'!I8+'[2]Apr-Sep''25'!I8 -> 558 | I8: =H8/G8 -> 0.93 | J8: ='[2]Oct-Dec''25'!K8+'[2]Apr-Sep''25'!K8 -> 6 | K8: ='[2]Oct-Dec''25'!L8+'[2]Apr-Sep''25'!L8 -> 6 | L8: =K8/J8 -> 1 | M8: ='[2]Oct-Dec''25'!N8+'[2]Apr-Sep''25'!N8 -> 543 | N8: ='[2]Oct-Dec''25'!O8+'[2]Apr-Sep''25'!O8 -> 540 | O8: =N8/M8 -> 0.99447514 | P8: ='[2]Oct-Dec''25'!Q8+'[2]Apr-Sep''25'!Q8 -> 481 | Q8: ='[2]Oct-Dec''25'!R8+'[2]Apr-Sep''25'!R8 -> 336 | R8: =Q8/P8 -> 0.6985447 | S8: ='[2]Oct-Dec''25'!T8+'[2]Apr-Sep''25'!T8 -> 1688 | T8: ='[2]Oct-Dec''25'!U8+'[2]Apr-Sep''25'!U8 -> 698 | U8: =T8/S8 -> 0.41350711 | V8: ='[2]Oct-Dec''25'!W8+'[2]Apr-Sep''25'!W8 -> 1307 | W8: ='[2]Oct-Dec''25'!Y8+'[2]Apr-Sep''25'!Y8 -> 398 | X8: =W8/V8 -> 0.30451415 | Y8: ='[2]Oct-Dec''25'!AA8+'[2]Apr-Sep''25'!AA8 -> 29 | Z8: ='[2]Oct-Dec''25'!AB8+'[2]Apr-Sep''25'!AB8 -> 29 | AA8: =Z8/Y8 -> 1 | AB8: ='[2]Oct-Dec''25'!AD8+'[2]Apr-Sep''25'!AD8 -> 26 | AC8: ='[2]Oct-Dec''25'!AE8+'[2]Apr-Sep''25'!AE8 -> 26 | AD8: =AC8/AB8 -> 1 | AE8: ='[2]Oct-Dec''25'!AJ8+'[2]Apr-Sep''25'!AJ8 -> 525 | AF8: ='[2]Oct-Dec''25'!AK8+'[2]Apr-Sep''25'!AK8 -> 418 | AG8: =AF8/AE8 -> 0.79619048 | AH8: ='[2]Oct-Dec''25'!AM8+'[2]Apr-Sep''25'!AM8 -> 0 | AI8: ='[2]Oct-Dec''25'!AN8+'[2]Apr-Sep''25'!AN8 -> 0 | AJ8: =AI8/AH8 -> #DIV/0! | AK8: ='[2]Oct-Dec''25'!AP8+'[2]Apr-Sep''25'!AP8 -> 35 | AL8: ='[2]Oct-Dec''25'!AQ8+'[2]Apr-Sep''25'!AQ8 -> 22 | AM8: =AL8/AK8 -> 0.62857143 | AN8: ='[2]Oct-Dec''25'!AS8+'[2]Apr-Sep''25'!AS8 -> 0 | AO8: ='[2]Oct-Dec''25'!AT8+'[2]Apr-Sep''25'!AT8 -> 48 | AP8: =AO8/AN8 -> #DIV/0! | AQ8: ='[2]Oct-Dec''25'!AV8+'[2]Apr-Sep''25'!AV8 -> 0 | AR8: ='[2]Oct-Dec''25'!AW8+'[2]Apr-Sep''25'!AW8 -> 0 | AS8: =AR8/AQ8 -> #DIV/0! | AT8: ='[2]Oct-Dec''25'!AY8+'[2]Apr-Sep''25'!AY8 -> 0 | AU8: ='[2]Oct-Dec''25'!AZ8+'[2]Apr-Sep''25'!AZ8 -> 0 | AV8: =AU8/AT8 -> #DIV/0! | AW8: =AN8+AQ8+AT8 -> 0 | AX8: =AO8+AR8+AU8 -> 48 | AY8: =AX8/AW8 -> #DIV/0! | AZ8: ='[2]Oct-Dec''25'!BB8+'[2]Apr-Sep''25'!BB8 -> 0 | BA8: ='[2]Oct-Dec''25'!BC8+'[2]Apr-Sep''25'!BC8 -> 0 | BB8: =IFERROR(BA8/AZ8,0) -> 0 | BC8: ='[2]Oct-Dec''25'!BE8+'[2]Apr-Sep''25'!BE8 -> 4 | BD8: ='[2]Oct-Dec''25'!BF8+'[2]Apr-Sep''25'!BF8 -> 4 | BE8: =IFERROR(BD8/BC8,0) -> 1 | BF8: ='[2]Oct-Dec''25'!BH8+'[2]Apr-Sep''25'!BH8 -> 0 | BG8: ='[2]Oct-Dec''25'!BI8+'[2]Apr-Sep''25'!BI8 -> 0 | BH8: =IFERROR(BG8/BF8,0) -> 0 | BI8: ='[2]Oct-Dec''25'!BK8+'[2]Apr-Sep''25'!BK8 -> 4 | BJ8: ='[2]Oct-Dec''25'!BL8+'[2]Apr-Sep''25'!BL8 -> 6 | BK8: =IFERROR(BJ8/BI8,0) -> 1.5 | BL8: ='[2]Oct-Dec''25'!BN8+'[2]Apr-Sep''25'!BN8 -> 0 | BM8: ='[2]Oct-Dec''25'!BO8+'[2]Apr-Sep''25'!BO8 -> 0 | BN8: =IFERROR(BM8/BL8,0) -> 0 | BO8: ='[2]Oct-Dec''25'!BQ8+'[2]Apr-Sep''25'!BQ8 -> 1 | BP8: ='[2]Oct-Dec''25'!BR8+'[2]Apr-Sep''25'!BR8 -> 1 | BQ8: =IFERROR(BP8/BO8,0) -> 1 | BR8: ='[2]Oct-Dec''25'!BT8+'[2]Apr-Sep''25'!BT8 -> 0 | BS8: ='[2]Oct-Dec''25'!BU8+'[2]Apr-Sep''25'!BU8 -> 0 | BT8: =IFERROR(BS8/BR8,0) -> 0 | BU8: ='[2]Oct-Dec''25'!BW8+'[2]Apr-Sep''25'!BW8 -> 0 | BV8: ='[2]Oct-Dec''25'!BX8+'[2]Apr-Sep''25'!BX8 -> 0 | BW8: =IFERROR(BV8/BU8,0) -> 0 | BX8: ='[2]Oct-Dec''25'!BZ8+'[2]Apr-Sep''25'!BZ8 -> 558 | BY8: ='[2]Oct-Dec''25'!CA8+'[2]Apr-Sep''25'!CA8 -> 459 | BZ8: =IFERROR(BY8/BX8,0) -> 0.82258065 | CA8: ='[2]Oct-Dec''25'!CC8+'[2]Apr-Sep''25'!CC8 -> 10 | CB8: ='[2]Oct-Dec''25'!CD8+'[2]Apr-Sep''25'!CD8 -> 10 | CC8: =IFERROR(CB8/CA8,0) -> 1 | CD8: ='[2]Oct-Dec''25'!CF8+'[2]Apr-Sep''25'!CF8 -> 0 | CE8: ='[2]Oct-Dec''25'!CG8+'[2]Apr-Sep''25'!CG8 -> 0 | CF8: =IFERROR(CE8/CD8,0) -> 0
A9: ='[2]Oct-Dec''25'!A9 -> 3 | B9: ='[2]Oct-Dec''25'!B9 -> CHRI | C9: ='[2]Oct-Dec''25'!C9 -> Assam | D9: ='[2]Oct-Dec''25'!D9 -> DESHABANDHU CLUB | E9: ='[2]Oct-Dec''25'!E9 -> CACHAR | F9: Apr-Dec'25 | G9: ='[2]Oct-Dec''25'!H9+'[2]Apr-Sep''25'!H9 -> 439 | H9: ='[2]Oct-Dec''25'!I9+'[2]Apr-Sep''25'!I9 -> 465 | I9: =H9/G9 -> 1.0592255 | J9: ='[2]Oct-Dec''25'!K9+'[2]Apr-Sep''25'!K9 -> 73 | K9: ='[2]Oct-Dec''25'!L9+'[2]Apr-Sep''25'!L9 -> 34 | L9: =K9/J9 -> 0.46575342 | M9: ='[2]Oct-Dec''25'!N9+'[2]Apr-Sep''25'!N9 -> 448 | N9: ='[2]Oct-Dec''25'!O9+'[2]Apr-Sep''25'!O9 -> 441 | O9: =N9/M9 -> 0.984375 | P9: ='[2]Oct-Dec''25'!Q9+'[2]Apr-Sep''25'!Q9 -> 370 | Q9: ='[2]Oct-Dec''25'!R9+'[2]Apr-Sep''25'!R9 -> 306 | R9: =Q9/P9 -> 0.82702703 | S9: ='[2]Oct-Dec''25'!T9+'[2]Apr-Sep''25'!T9 -> 2941 | T9: ='[2]Oct-Dec''25'!U9+'[2]Apr-Sep''25'!U9 -> 2583 | U9: =T9/S9 -> 0.8782727 | V9: ='[2]Oct-Dec''25'!W9+'[2]Apr-Sep''25'!W9 -> 1444 | W9: ='[2]Oct-Dec''25'!Y9+'[2]Apr-Sep''25'!Y9 -> 815 | X9: =W9/V9 -> 0.56440443 | Y9: ='[2]Oct-Dec''25'!AA9+'[2]Apr-Sep''25'!AA9 -> 320 | Z9: ='[2]Oct-Dec''25'!AB9+'[2]Apr-Sep''25'!AB9 -> 320 | AA9: =Z9/Y9 -> 1 | AB9: ='[2]Oct-Dec''25'!AD9+'[2]Apr-Sep''25'!AD9 -> 106 | AC9: ='[2]Oct-Dec''25'!AE9+'[2]Apr-Sep''25'!AE9 -> 77 | AD9: =AC9/AB9 -> 0.72641509 | AE9: ='[2]Oct-Dec''25'!AJ9+'[2]Apr-Sep''25'!AJ9 -> 382 | AF9: ='[2]Oct-Dec''25'!AK9+'[2]Apr-Sep''25'!AK9 -> 321 | AG9: =AF9/AE9 -> 0.84031414 | AH9: ='[2]Oct-Dec''25'!AM9+'[2]Apr-Sep''25'!AM9 -> 1 | AI9: ='[2]Oct-Dec''25'!AN9+'[2]Apr-Sep''25'!AN9 -> 1 | AJ9: =AI9/AH9 -> 1 | AK9: ='[2]Oct-Dec''25'!AP9+'[2]Apr-Sep''25'!AP9 -> 118 | AL9: ='[2]Oct-Dec''25'!AQ9+'[2]Apr-Sep''25'!AQ9 -> 116 | AM9: =AL9/AK9 -> 0.98305085 | AN9: ='[2]Oct-Dec''25'!AS9+'[2]Apr-Sep''25'!AS9 -> 137 | AO9: ='[2]Oct-Dec''25'!AT9+'[2]Apr-Sep''25'!AT9 -> 131 | AP9: =AO9/AN9 -> 0.95620438 | AQ9: ='[2]Oct-Dec''25'!AV9+'[2]Apr-Sep''25'!AV9 -> 4 | AR9: ='[2]Oct-Dec''25'!AW9+'[2]Apr-Sep''25'!AW9 -> 4 | AS9: =AR9/AQ9 -> 1 | AT9: ='[2]Oct-Dec''25'!AY9+'[2]Apr-Sep''25'!AY9 -> 86 | AU9: ='[2]Oct-Dec''25'!AZ9+'[2]Apr-Sep''25'!AZ9 -> 85 | AV9: =AU9/AT9 -> 0.98837209 | AW9: =AN9+AQ9+AT9 -> 227 | AX9: =AO9+AR9+AU9 -> 220 | AY9: =AX9/AW9 -> 0.969163 | AZ9: ='[2]Oct-Dec''25'!BB9+'[2]Apr-Sep''25'!BB9 -> 73 | BA9: ='[2]Oct-Dec''25'!BC9+'[2]Apr-Sep''25'!BC9 -> 72 | BB9: =IFERROR(BA9/AZ9,0) -> 0.98630137 | BC9: ='[2]Oct-Dec''25'!BE9+'[2]Apr-Sep''25'!BE9 -> 25 | BD9: ='[2]Oct-Dec''25'!BF9+'[2]Apr-Sep''25'!BF9 -> 28 | BE9: =IFERROR(BD9/BC9,0) -> 1.12 | BF9: ='[2]Oct-Dec''25'!BH9+'[2]Apr-Sep''25'!BH9 -> 37 | BG9: ='[2]Oct-Dec''25'!BI9+'[2]Apr-Sep''25'!BI9 -> 37 | BH9: =IFERROR(BG9/BF9,0) -> 1 | BI9: ='[2]Oct-Dec''25'!BK9+'[2]Apr-Sep''25'!BK9 -> 28 | BJ9: ='[2]Oct-Dec''25'!BL9+'[2]Apr-Sep''25'!BL9 -> 27 | BK9: =IFERROR(BJ9/BI9,0) -> 0.96428571 | BL9: ='[2]Oct-Dec''25'!BN9+'[2]Apr-Sep''25'!BN9 -> 27 | BM9: ='[2]Oct-Dec''25'!BO9+'[2]Apr-Sep''25'!BO9 -> 26 | BN9: =IFERROR(BM9/BL9,0) -> 0.96296296 | BO9: ='[2]Oct-Dec''25'!BQ9+'[2]Apr-Sep''25'!BQ9 -> 12 | BP9: ='[2]Oct-Dec''25'!BR9+'[2]Apr-Sep''25'!BR9 -> 11 | BQ9: =IFERROR(BP9/BO9,0) -> 0.91666667 | BR9: ='[2]Oct-Dec''25'!BT9+'[2]Apr-Sep''25'!BT9 -> 29 | BS9: ='[2]Oct-Dec''25'!BU9+'[2]Apr-Sep''25'!BU9 -> 21 | BT9: =IFERROR(BS9/BR9,0) -> 0.72413793 | BU9: ='[2]Oct-Dec''25'!BW9+'[2]Apr-Sep''25'!BW9 -> 2 | BV9: ='[2]Oct-Dec''25'!BX9+'[2]Apr-Sep''25'!BX9 -> 2 | BW9: =IFERROR(BV9/BU9,0) -> 1 | BX9: ='[2]Oct-Dec''25'!BZ9+'[2]Apr-Sep''25'!BZ9 -> 465 | BY9: ='[2]Oct-Dec''25'!CA9+'[2]Apr-Sep''25'!CA9 -> 480 | BZ9: =IFERROR(BY9/BX9,0) -> 1.0322581 | CA9: ='[2]Oct-Dec''25'!CC9+'[2]Apr-Sep''25'!CC9 -> 121 | CB9: ='[2]Oct-Dec''25'!CD9+'[2]Apr-Sep''25'!CD9 -> 89 | CC9: =IFERROR(CB9/CA9,0) -> 0.73553719 | CD9: ='[2]Oct-Dec''25'!CF9+'[2]Apr-Sep''25'!CF9 -> 57 | CE9: ='[2]Oct-Dec''25'!CG9+'[2]Apr-Sep''25'!CG9 -> 93 | CF9: =IFERROR(CE9/CD9,0) -> 1.6315789
A10: ='[2]Oct-Dec''25'!A10 -> 4 | B10: ='[2]Oct-Dec''25'!B10 -> CHRI | C10: ='[2]Oct-Dec''25'!C10 -> Assam | D10: ='[2]Oct-Dec''25'!D10 -> ASSAM NETWORK OF POSITIVE PEOPLE(ANP+), KAMRUP | E10: ='[2]Oct-Dec''25'!E10 -> KAMRUP | F10: Apr-Dec'25 | G10: ='[2]Oct-Dec''25'!H10+'[2]Apr-Sep''25'!H10 -> 1353 | H10: ='[2]Oct-Dec''25'!I10+'[2]Apr-Sep''25'!I10 -> 1207 | I10: =H10/G10 -> 0.89209165 | J10: ='[2]Oct-Dec''25'!K10+'[2]Apr-Sep''25'!K10 -> 0 | K10: ='[2]Oct-Dec''25'!L10+'[2]Apr-Sep''25'!L10 -> 0 | M10: ='[2]Oct-Dec''25'!N10+'[2]Apr-Sep''25'!N10 -> 761 | N10: ='[2]Oct-Dec''25'!O10+'[2]Apr-Sep''25'!O10 -> 413 | O10: =N10/M10 -> 0.54270696 | P10: ='[2]Oct-Dec''25'!Q10+'[2]Apr-Sep''25'!Q10 -> 198 | Q10: ='[2]Oct-Dec''25'!R10+'[2]Apr-Sep''25'!R10 -> 164 | R10: =Q10/P10 -> 0.82828283 | S10: ='[2]Oct-Dec''25'!T10+'[2]Apr-Sep''25'!T10 -> 3626 | T10: ='[2]Oct-Dec''25'!U10+'[2]Apr-Sep''25'!U10 -> 1183 | U10: =T10/S10 -> 0.32625483 | V10: ='[2]Oct-Dec''25'!W10+'[2]Apr-Sep''25'!W10 -> 5386 | W10: ='[2]Oct-Dec''25'!Y10+'[2]Apr-Sep''25'!Y10 -> 949 | X10: =W10/V10 -> 0.17619755 | Y10: ='[2]Oct-Dec''25'!AA10+'[2]Apr-Sep''25'!AA10 -> 1094 | Z10: ='[2]Oct-Dec''25'!AB10+'[2]Apr-Sep''25'!AB10 -> 148 | AA10: =Z10/Y10 -> 0.13528336 | AB10: ='[2]Oct-Dec''25'!AD10+'[2]Apr-Sep''25'!AD10 -> 0 | AC10: ='[2]Oct-Dec''25'!AE10+'[2]Apr-Sep''25'!AE10 -> 0 | AD10: =AC10/AB10 -> #DIV/0! | AE10: ='[2]Oct-Dec''25'!AJ10+'[2]Apr-Sep''25'!AJ10 -> 2423 | AF10: ='[2]Oct-Dec''25'!AK10+'[2]Apr-Sep''25'!AK10 -> 963 | AG10: =AF10/AE10 -> 0.39744119 | AH10: ='[2]Oct-Dec''25'!AM10+'[2]Apr-Sep''25'!AM10 -> 0 | AI10: ='[2]Oct-Dec''25'!AN10+'[2]Apr-Sep''25'!AN10 -> 0 | AJ10: =AI10/AH10 -> #DIV/0! | AK10: ='[2]Oct-Dec''25'!AP10+'[2]Apr-Sep''25'!AP10 -> 208 | AL10: ='[2]Oct-Dec''25'!AQ10+'[2]Apr-Sep''25'!AQ10 -> 40 | AM10: =AL10/AK10 -> 0.19230769 | AN10: ='[2]Oct-Dec''25'!AS10+'[2]Apr-Sep''25'!AS10 -> 2326 | AO10: ='[2]Oct-Dec''25'!AT10+'[2]Apr-Sep''25'!AT10 -> 2291 | AP10: =AO10/AN10 -> 0.98495271 | AQ10: ='[2]Oct-Dec''25'!AV10+'[2]Apr-Sep''25'!AV10 -> 0 | AR10: ='[2]Oct-Dec''25'!AW10+'[2]Apr-Sep''25'!AW10 -> 0 | AS10: =AR10/AQ10 -> #DIV/0! | AT10: ='[2]Oct-Dec''25'!AY10+'[2]Apr-Sep''25'!AY10 -> 0 | AU10: ='[2]Oct-Dec''25'!AZ10+'[2]Apr-Sep''25'!AZ10 -> 0 | AV10: =AU10/AT10 -> #DIV/0! | AW10: =AN10+AQ10+AT10 -> 2326 | AX10: =AO10+AR10+AU10 -> 2291 | AY10: =AX10/AW10 -> 0.98495271 | AZ10: ='[2]Oct-Dec''25'!BB10+'[2]Apr-Sep''25'!BB10 -> 1837 | BA10: ='[2]Oct-Dec''25'!BC10+'[2]Apr-Sep''25'!BC10 -> 152 | BB10: =IFERROR(BA10/AZ10,0) -> 0.082743604 | BC10: ='[2]Oct-Dec''25'!BE10+'[2]Apr-Sep''25'!BE10 -> 0 | BD10: ='[2]Oct-Dec''25'!BF10+'[2]Apr-Sep''25'!BF10 -> 0 | BE10: =IFERROR(BD10/BC10,0) -> 0 | BF10: ='[2]Oct-Dec''25'!BH10+'[2]Apr-Sep''25'!BH10 -> 38 | BG10: ='[2]Oct-Dec''25'!BI10+'[2]Apr-Sep''25'!BI10 -> 38 | BH10: =IFERROR(BG10/BF10,0) -> 1 | BI10: ='[2]Oct-Dec''25'!BK10+'[2]Apr-Sep''25'!BK10 -> 11 | BJ10: ='[2]Oct-Dec''25'!BL10+'[2]Apr-Sep''25'!BL10 -> 10 | BK10: =IFERROR(BJ10/BI10,0) -> 0.90909091 | BL10: ='[2]Oct-Dec''25'!BN10+'[2]Apr-Sep''25'!BN10 -> 12 | BM10: ='[2]Oct-Dec''25'!BO10+'[2]Apr-Sep''25'!BO10 -> 12 | BN10: =IFERROR(BM10/BL10,0) -> 1 | BO10: ='[2]Oct-Dec''25'!BQ10+'[2]Apr-Sep''25'!BQ10 -> 4 | BP10: ='[2]Oct-Dec''25'!BR10+'[2]Apr-Sep''25'!BR10 -> 6 | BQ10: =IFERROR(BP10/BO10,0) -> 1.5 | BR10: ='[2]Oct-Dec''25'!BT10+'[2]Apr-Sep''25'!BT10 -> 3 | BS10: ='[2]Oct-Dec''25'!BU10+'[2]Apr-Sep''25'!BU10 -> 1 | BT10: =IFERROR(BS10/BR10,0) -> 0.33333333 | BU10: ='[2]Oct-Dec''25'!BW10+'[2]Apr-Sep''25'!BW10 -> 0 | BV10: ='[2]Oct-Dec''25'!BX10+'[2]Apr-Sep''25'!BX10 -> 0 | BW10: =IFERROR(BV10/BU10,0) -> 0 | BX10: ='[2]Oct-Dec''25'!BZ10+'[2]Apr-Sep''25'!BZ10 -> 1207 | BY10: ='[2]Oct-Dec''25'!CA10+'[2]Apr-Sep''25'!CA10 -> 988 | BZ10: =IFERROR(BY10/BX10,0) -> 0.81855841 | CA10: ='[2]Oct-Dec''25'!CC10+'[2]Apr-Sep''25'!CC10 -> 10 | CB10: ='[2]Oct-Dec''25'!CD10+'[2]Apr-Sep''25'!CD10 -> 48 | CC10: =IFERROR(CB10/CA10,0) -> 4.8 | CD10: ='[2]Oct-Dec''25'!CF10+'[2]Apr-Sep''25'!CF10 -> 0 | CE10: ='[2]Oct-Dec''25'!CG10+'[2]Apr-Sep''25'!CG10 -> 0 | CF10: =IFERROR(CE10/CD10,0) -> 0
A11: ='[2]Oct-Dec''25'!A11 -> 5 | B11: ='[2]Oct-Dec''25'!B11 -> CHRI | C11: ='[2]Oct-Dec''25'!C11 -> Bihar | D11: ='[2]Oct-Dec''25'!D11 -> BNP+ | E11: ='[2]Oct-Dec''25'!E11 -> BHAGALPUR | F11: Apr-Dec'25 | G11: ='[2]Oct-Dec''25'!H11+'[2]Apr-Sep''25'!H11 -> 443 | H11: ='[2]Oct-Dec''25'!I11+'[2]Apr-Sep''25'!I11 -> 497 | I11: =H11/G11 -> 1.1218962 | J11: ='[2]Oct-Dec''25'!K11+'[2]Apr-Sep''25'!K11 -> 444 | K11: ='[2]Oct-Dec''25'!L11+'[2]Apr-Sep''25'!L11 -> 444 | L11: =K11/J11 -> 1 | M11: ='[2]Oct-Dec''25'!N11+'[2]Apr-Sep''25'!N11 -> 392 | N11: ='[2]Oct-Dec''25'!O11+'[2]Apr-Sep''25'!O11 -> 390 | O11: =N11/M11 -> 0.99489796 | P11: ='[2]Oct-Dec''25'!Q11+'[2]Apr-Sep''25'!Q11 -> 348 | Q11: ='[2]Oct-Dec''25'!R11+'[2]Apr-Sep''25'!R11 -> 328 | R11: =Q11/P11 -> 0.94252874 | S11: ='[2]Oct-Dec''25'!T11+'[2]Apr-Sep''25'!T11 -> 1907 | T11: ='[2]Oct-Dec''25'!U11+'[2]Apr-Sep''25'!U11 -> 1615 | U11: =T11/S11 -> 0.84687992 | V11: ='[2]Oct-Dec''25'!W11+'[2]Apr-Sep''25'!W11 -> 1340 | W11: ='[2]Oct-Dec''25'!Y11+'[2]Apr-Sep''25'!Y11 -> 993 | X11: =W11/V11 -> 0.74104478 | Y11: ='[2]Oct-Dec''25'!AA11+'[2]Apr-Sep''25'!AA11 -> 62 | Z11: ='[2]Oct-Dec''25'!AB11+'[2]Apr-Sep''25'!AB11 -> 62 | AA11: =Z11/Y11 -> 1 | AB11: ='[2]Oct-Dec''25'!AD11+'[2]Apr-Sep''25'!AD11 -> 9 | AC11: ='[2]Oct-Dec''25'!AE11+'[2]Apr-Sep''25'!AE11 -> 9 | AD11: =AC11/AB11 -> 1 | AE11: ='[2]Oct-Dec''25'!AJ11+'[2]Apr-Sep''25'!AJ11 -> 2189 | AF11: ='[2]Oct-Dec''25'!AK11+'[2]Apr-Sep''25'!AK11 -> 2004 | AG11: =AF11/AE11 -> 0.91548652 | AH11: ='[2]Oct-Dec''25'!AM11+'[2]Apr-Sep''25'!AM11 -> 0 | AI11: ='[2]Oct-Dec''25'!AN11+'[2]Apr-Sep''25'!AN11 -> 0 | AJ11: =AI11/AH11 -> #DIV/0! | AK11: ='[2]Oct-Dec''25'!AP11+'[2]Apr-Sep''25'!AP11 -> 150 | AL11: ='[2]Oct-Dec''25'!AQ11+'[2]Apr-Sep''25'!AQ11 -> 128 | AM11: =AL11/AK11 -> 0.85333333 | AN11: ='[2]Oct-Dec''25'!AS11+'[2]Apr-Sep''25'!AS11 -> 83 | AO11: ='[2]Oct-Dec''25'!AT11+'[2]Apr-Sep''25'!AT11 -> 79 | AP11: =AO11/AN11 -> 0.95180723 | AQ11: ='[2]Oct-Dec''25'!AV11+'[2]Apr-Sep''25'!AV11 -> 0 | AR11: ='[2]Oct-Dec''25'!AW11+'[2]Apr-Sep''25'!AW11 -> 0 | AS11: =AR11/AQ11 -> #DIV/0! | AT11: ='[2]Oct-Dec''25'!AY11+'[2]Apr-Sep''25'!AY11 -> 163 | AU11: ='[2]Oct-Dec''25'!AZ11+'[2]Apr-Sep''25'!AZ11 -> 163 | AV11: =AU11/AT11 -> 1 | AW11: =AN11+AQ11+AT11 -> 246 | AX11: =AO11+AR11+AU11 -> 242 | AY11: =AX11/AW11 -> 0.98373984 | AZ11: ='[2]Oct-Dec''25'!BB11+'[2]Apr-Sep''25'!BB11 -> 96 | BA11: ='[2]Oct-Dec''25'!BC11+'[2]Apr-Sep''25'!BC11 -> 91 | BB11: =IFERROR(BA11/AZ11,0) -> 0.94791667 | BC11: ='[2]Oct-Dec''25'!BE11+'[2]Apr-Sep''25'!BE11 -> 24 | BD11: ='[2]Oct-Dec''25'!BF11+'[2]Apr-Sep''25'!BF11 -> 24 | BE11: =IFERROR(BD11/BC11,0) -> 1 | BF11: ='[2]Oct-Dec''25'!BH11+'[2]Apr-Sep''25'!BH11 -> 20 | BG11: ='[2]Oct-Dec''25'!BI11+'[2]Apr-Sep''25'!BI11 -> 20 | BH11: =IFERROR(BG11/BF11,0) -> 1 | BI11: ='[2]Oct-Dec''25'!BK11+'[2]Apr-Sep''25'!BK11 -> 32 | BJ11: ='[2]Oct-Dec''25'!BL11+'[2]Apr-Sep''25'!BL11 -> 36 | BK11: =IFERROR(BJ11/BI11,0) -> 1.125 | BL11: ='[2]Oct-Dec''25'!BN11+'[2]Apr-Sep''25'!BN11 -> 20 | BM11: ='[2]Oct-Dec''25'!BO11+'[2]Apr-Sep''25'!BO11 -> 20 | BN11: =IFERROR(BM11/BL11,0) -> 1 | BO11: ='[2]Oct-Dec''25'!BQ11+'[2]Apr-Sep''25'!BQ11 -> 25 | BP11: ='[2]Oct-Dec''25'!BR11+'[2]Apr-Sep''25'!BR11 -> 24 | BQ11: =IFERROR(BP11/BO11,0) -> 0.96 | BR11: ='[2]Oct-Dec''25'!BT11+'[2]Apr-Sep''25'!BT11 -> 37 | BS11: ='[2]Oct-Dec''25'!BU11+'[2]Apr-Sep''25'!BU11 -> 34 | BT11: =IFERROR(BS11/BR11,0) -> 0.91891892 | BU11: ='[2]Oct-Dec''25'!BW11+'[2]Apr-Sep''25'!BW11 -> 0 | BV11: ='[2]Oct-Dec''25'!BX11+'[2]Apr-Sep''25'!BX11 -> 0 | BW11: =IFERROR(BV11/BU11,0) -> 0 | BX11: ='[2]Oct-Dec''25'!BZ11+'[2]Apr-Sep''25'!BZ11 -> 497 | BY11: ='[2]Oct-Dec''25'!CA11+'[2]Apr-Sep''25'!CA11 -> 1278 | BZ11: =IFERROR(BY11/BX11,0) -> 2.5714286 | CA11: ='[2]Oct-Dec''25'!CC11+'[2]Apr-Sep''25'!CC11 -> 72 | CB11: ='[2]Oct-Dec''25'!CD11+'[2]Apr-Sep''25'!CD11 -> 71 | CC11: =IFERROR(CB11/CA11,0) -> 0.98611111 | CD11: ='[2]Oct-Dec''25'!CF11+'[2]Apr-Sep''25'!CF11 -> 0 | CE11: ='[2]Oct-Dec''25'!CG11+'[2]Apr-Sep''25'!CG11 -> 0 | CF11: =IFERROR(CE11/CD11,0) -> 0
A12: ='[2]Oct-Dec''25'!A12 -> 6 | B12: ='[2]Oct-Dec''25'!B12 -> CHRI | C12: ='[2]Oct-Dec''25'!C12 -> Bihar | D12: ='[2]Oct-Dec''25'!D12 -> BNP+ | E12: ='[2]Oct-Dec''25'!E12 -> DARBHANGA | F12: Apr-Dec'25 | G12: ='[2]Oct-Dec''25'!H12+'[2]Apr-Sep''25'!H12 -> 250 | H12: ='[2]Oct-Dec''25'!I12+'[2]Apr-Sep''25'!I12 -> 240 | I12: =H12/G12 -> 0.96 | J12: ='[2]Oct-Dec''25'!K12+'[2]Apr-Sep''25'!K12 -> 192 | K12: ='[2]Oct-Dec''25'!L12+'[2]Apr-Sep''25'!L12 -> 189 | L12: =K12/J12 -> 0.984375 | M12: ='[2]Oct-Dec''25'!N12+'[2]Apr-Sep''25'!N12 -> 247 | N12: ='[2]Oct-Dec''25'!O12+'[2]Apr-Sep''25'!O12 -> 247 | O12: =N12/M12 -> 1 | P12: ='[2]Oct-Dec''25'!Q12+'[2]Apr-Sep''25'!Q12 -> 220 | Q12: ='[2]Oct-Dec''25'!R12+'[2]Apr-Sep''25'!R12 -> 202 | R12: =Q12/P12 -> 0.91818182 | S12: ='[2]Oct-Dec''25'!T12+'[2]Apr-Sep''25'!T12 -> 1167 | T12: ='[2]Oct-Dec''25'!U12+'[2]Apr-Sep''25'!U12 -> 1053 | U12: =T12/S12 -> 0.90231362 | V12: ='[2]Oct-Dec''25'!W12+'[2]Apr-Sep''25'!W12 -> 355 | W12: ='[2]Oct-Dec''25'!Y12+'[2]Apr-Sep''25'!Y12 -> 308 | X12: =W12/V12 -> 0.86760563 | Y12: ='[2]Oct-Dec''25'!AA12+'[2]Apr-Sep''25'!AA12 -> 0 | Z12: ='[2]Oct-Dec''25'!AB12+'[2]Apr-Sep''25'!AB12 -> 0 | AA12: =Z12/Y12 -> #DIV/0! | AB12: ='[2]Oct-Dec''25'!AD12+'[2]Apr-Sep''25'!AD12 -> 0 | AC12: ='[2]Oct-Dec''25'!AE12+'[2]Apr-Sep''25'!AE12 -> 0 | AD12: =AC12/AB12 -> #DIV/0! | AE12: ='[2]Oct-Dec''25'!AJ12+'[2]Apr-Sep''25'!AJ12 -> 916 | AF12: ='[2]Oct-Dec''25'!AK12+'[2]Apr-Sep''25'!AK12 -> 915 | AG12: =AF12/AE12 -> 0.9989083 | AH12: ='[2]Oct-Dec''25'!AM12+'[2]Apr-Sep''25'!AM12 -> 0 | AI12: ='[2]Oct-Dec''25'!AN12+'[2]Apr-Sep''25'!AN12 -> 0 | AJ12: =AI12/AH12 -> #DIV/0! | AK12: ='[2]Oct-Dec''25'!AP12+'[2]Apr-Sep''25'!AP12 -> 81 | AL12: ='[2]Oct-Dec''25'!AQ12+'[2]Apr-Sep''25'!AQ12 -> 42 | AM12: =AL12/AK12 -> 0.51851852 | AN12: ='[2]Oct-Dec''25'!AS12+'[2]Apr-Sep''25'!AS12 -> 56 | AO12: ='[2]Oct-Dec''25'!AT12+'[2]Apr-Sep''25'!AT12 -> 40 | AP12: =AO12/AN12 -> 0.71428571 | AQ12: ='[2]Oct-Dec''25'!AV12+'[2]Apr-Sep''25'!AV12 -> 0 | AR12: ='[2]Oct-Dec''25'!AW12+'[2]Apr-Sep''25'!AW12 -> 0 | AS12: =AR12/AQ12 -> #DIV/0! | AT12: ='[2]Oct-Dec''25'!AY12+'[2]Apr-Sep''25'!AY12 -> 91 | AU12: ='[2]Oct-Dec''25'!AZ12+'[2]Apr-Sep''25'!AZ12 -> 78 | AV12: =AU12/AT12 -> 0.85714286 | AW12: =AN12+AQ12+AT12 -> 147 | AX12: =AO12+AR12+AU12 -> 118 | AY12: =AX12/AW12 -> 0.80272109 | AZ12: ='[2]Oct-Dec''25'!BB12+'[2]Apr-Sep''25'!BB12 -> 69 | BA12: ='[2]Oct-Dec''25'!BC12+'[2]Apr-Sep''25'!BC12 -> 57 | BB12: =IFERROR(BA12/AZ12,0) -> 0.82608696 | BC12: ='[2]Oct-Dec''25'!BE12+'[2]Apr-Sep''25'!BE12 -> 9 | BD12: ='[2]Oct-Dec''25'!BF12+'[2]Apr-Sep''25'!BF12 -> 9 | BE12: =IFERROR(BD12/BC12,0) -> 1 | BF12: ='[2]Oct-Dec''25'!BH12+'[2]Apr-Sep''25'!BH12 -> 10 | BG12: ='[2]Oct-Dec''25'!BI12+'[2]Apr-Sep''25'!BI12 -> 10 | BH12: =IFERROR(BG12/BF12,0) -> 1 | BI12: ='[2]Oct-Dec''25'!BK12+'[2]Apr-Sep''25'!BK12 -> 20 | BJ12: ='[2]Oct-Dec''25'!BL12+'[2]Apr-Sep''25'!BL12 -> 19 | BK12: =IFERROR(BJ12/BI12,0) -> 0.95 | BL12: ='[2]Oct-Dec''25'!BN12+'[2]Apr-Sep''25'!BN12 -> 8 | BM12: ='[2]Oct-Dec''25'!BO12+'[2]Apr-Sep''25'!BO12 -> 7 | BN12: =IFERROR(BM12/BL12,0) -> 0.875 | BO12: ='[2]Oct-Dec''25'!BQ12+'[2]Apr-Sep''25'!BQ12 -> 7 | BP12: ='[2]Oct-Dec''25'!BR12+'[2]Apr-Sep''25'!BR12 -> 6 | BQ12: =IFERROR(BP12/BO12,0) -> 0.85714286 | BR12: ='[2]Oct-Dec''25'!BT12+'[2]Apr-Sep''25'!BT12 -> 13 | BS12: ='[2]Oct-Dec''25'!BU12+'[2]Apr-Sep''25'!BU12 -> 13 | BT12: =IFERROR(BS12/BR12,0) -> 1 | BU12: ='[2]Oct-Dec''25'!BW12+'[2]Apr-Sep''25'!BW12 -> 0 | BV12: ='[2]Oct-Dec''25'!BX12+'[2]Apr-Sep''25'!BX12 -> 0 | BW12: =IFERROR(BV12/BU12,0) -> 0 | BX12: ='[2]Oct-Dec''25'!BZ12+'[2]Apr-Sep''25'!BZ12 -> 240 | BY12: ='[2]Oct-Dec''25'!CA12+'[2]Apr-Sep''25'!CA12 -> 244 | BZ12: =IFERROR(BY12/BX12,0) -> 1.0166667 | CA12: ='[2]Oct-Dec''25'!CC12+'[2]Apr-Sep''25'!CC12 -> 48 | CB12: ='[2]Oct-Dec''25'!CD12+'[2]Apr-Sep''25'!CD12 -> 48 | CC12: =IFERROR(CB12/CA12,0) -> 1 | CD12: ='[2]Oct-Dec''25'!CF12+'[2]Apr-Sep''25'!CF12 -> 7 | CE12: ='[2]Oct-Dec''25'!CG12+'[2]Apr-Sep''25'!CG12 -> 7 | CF12: =IFERROR(CE12/CD12,0) -> 1
A13: ='[2]Oct-Dec''25'!A13 -> 7 | B13: ='[2]Oct-Dec''25'!B13 -> CHRI | C13: ='[2]Oct-Dec''25'!C13 -> Bihar | D13: ='[2]Oct-Dec''25'!D13 -> BJUP JEEVAN JYOTHI | E13: ='[2]Oct-Dec''25'!E13 -> GAYA | F13: Apr-Dec'25 | G13: ='[2]Oct-Dec''25'!H13+'[2]Apr-Sep''25'!H13 -> 350 | H13: ='[2]Oct-Dec''25'!I13+'[2]Apr-Sep''25'!I13 -> 317 | I13: =H13/G13 -> 0.90571429 | J13: ='[2]Oct-Dec''25'!K13+'[2]Apr-Sep''25'!K13 -> 264 | K13: ='[2]Oct-Dec''25'!L13+'[2]Apr-Sep''25'!L13 -> 235 | L13: =K13/J13 -> 0.89015152 | M13: ='[2]Oct-Dec''25'!N13+'[2]Apr-Sep''25'!N13 -> 318 | N13: ='[2]Oct-Dec''25'!O13+'[2]Apr-Sep''25'!O13 -> 314 | O13: =N13/M13 -> 0.98742138 | P13: ='[2]Oct-Dec''25'!Q13+'[2]Apr-Sep''25'!Q13 -> 294 | Q13: ='[2]Oct-Dec''25'!R13+'[2]Apr-Sep''25'!R13 -> 261 | R13: =Q13/P13 -> 0.8877551 | S13: ='[2]Oct-Dec''25'!T13+'[2]Apr-Sep''25'!T13 -> 948 | T13: ='[2]Oct-Dec''25'!U13+'[2]Apr-Sep''25'!U13 -> 730 | U13: =T13/S13 -> 0.77004219 | V13: ='[2]Oct-Dec''25'!W13+'[2]Apr-Sep''25'!W13 -> 431 | W13: ='[2]Oct-Dec''25'!Y13+'[2]Apr-Sep''25'!Y13 -> 360 | X13: =W13/V13 -> 0.83526682 | Y13: ='[2]Oct-Dec''25'!AA13+'[2]Apr-Sep''25'!AA13 -> 4 | Z13: ='[2]Oct-Dec''25'!AB13+'[2]Apr-Sep''25'!AB13 -> 4 | AA13: =Z13/Y13 -> 1 | AB13: ='[2]Oct-Dec''25'!AD13+'[2]Apr-Sep''25'!AD13 -> 10 | AC13: ='[2]Oct-Dec''25'!AE13+'[2]Apr-Sep''25'!AE13 -> 5 | AD13: =AC13/AB13 -> 0.5 | AE13: ='[2]Oct-Dec''25'!AJ13+'[2]Apr-Sep''25'!AJ13 -> 1602 | AF13: ='[2]Oct-Dec''25'!AK13+'[2]Apr-Sep''25'!AK13 -> 1578 | AG13: =AF13/AE13 -> 0.98501873 | AH13: ='[2]Oct-Dec''25'!AM13+'[2]Apr-Sep''25'!AM13 -> 0 | AI13: ='[2]Oct-Dec''25'!AN13+'[2]Apr-Sep''25'!AN13 -> 0 | AJ13: =AI13/AH13 -> #DIV/0! | AK13: ='[2]Oct-Dec''25'!AP13+'[2]Apr-Sep''25'!AP13 -> 44 | AL13: ='[2]Oct-Dec''25'!AQ13+'[2]Apr-Sep''25'!AQ13 -> 32 | AM13: =AL13/AK13 -> 0.72727273 | AN13: ='[2]Oct-Dec''25'!AS13+'[2]Apr-Sep''25'!AS13 -> 74 | AO13: ='[2]Oct-Dec''25'!AT13+'[2]Apr-Sep''25'!AT13 -> 74 | AP13: =AO13/AN13 -> 1 | AQ13: ='[2]Oct-Dec''25'!AV13+'[2]Apr-Sep''25'!AV13 -> 0 | AR13: ='[2]Oct-Dec''25'!AW13+'[2]Apr-Sep''25'!AW13 -> 0 | AS13: =AR13/AQ13 -> #DIV/0! | AT13: ='[2]Oct-Dec''25'!AY13+'[2]Apr-Sep''25'!AY13 -> 177 | AU13: ='[2]Oct-Dec''25'!AZ13+'[2]Apr-Sep''25'!AZ13 -> 177 | AV13: =AU13/AT13 -> 1 | AW13: =AN13+AQ13+AT13 -> 251 | AX13: =AO13+AR13+AU13 -> 251 | AY13: =AX13/AW13 -> 1 | AZ13: ='[2]Oct-Dec''25'!BB13+'[2]Apr-Sep''25'!BB13 -> 176 | BA13: ='[2]Oct-Dec''25'!BC13+'[2]Apr-Sep''25'!BC13 -> 176 | BB13: =IFERROR(BA13/AZ13,0) -> 1 | BC13: ='[2]Oct-Dec''25'!BE13+'[2]Apr-Sep''25'!BE13 -> 17 | BD13: ='[2]Oct-Dec''25'!BF13+'[2]Apr-Sep''25'!BF13 -> 17 | BE13: =IFERROR(BD13/BC13,0) -> 1 | BF13: ='[2]Oct-Dec''25'!BH13+'[2]Apr-Sep''25'!BH13 -> 25 | BG13: ='[2]Oct-Dec''25'!BI13+'[2]Apr-Sep''25'!BI13 -> 25 | BH13: =IFERROR(BG13/BF13,0) -> 1 | BI13: ='[2]Oct-Dec''25'!BK13+'[2]Apr-Sep''25'!BK13 -> 55 | BJ13: ='[2]Oct-Dec''25'!BL13+'[2]Apr-Sep''25'!BL13 -> 53 | BK13: =IFERROR(BJ13/BI13,0) -> 0.96363636 | BL13: ='[2]Oct-Dec''25'!BN13+'[2]Apr-Sep''25'!BN13 -> 36 | BM13: ='[2]Oct-Dec''25'!BO13+'[2]Apr-Sep''25'!BO13 -> 35 | BN13: =IFERROR(BM13/BL13,0) -> 0.97222222 | BO13: ='[2]Oct-Dec''25'!BQ13+'[2]Apr-Sep''25'!BQ13 -> 34 | BP13: ='[2]Oct-Dec''25'!BR13+'[2]Apr-Sep''25'!BR13 -> 33 | BQ13: =IFERROR(BP13/BO13,0) -> 0.97058824 | BR13: ='[2]Oct-Dec''25'!BT13+'[2]Apr-Sep''25'!BT13 -> 57 | BS13: ='[2]Oct-Dec''25'!BU13+'[2]Apr-Sep''25'!BU13 -> 53 | BT13: =IFERROR(BS13/BR13,0) -> 0.92982456 | BU13: ='[2]Oct-Dec''25'!BW13+'[2]Apr-Sep''25'!BW13 -> 0 | BV13: ='[2]Oct-Dec''25'!BX13+'[2]Apr-Sep''25'!BX13 -> 0 | BW13: =IFERROR(BV13/BU13,0) -> 0 | BX13: ='[2]Oct-Dec''25'!BZ13+'[2]Apr-Sep''25'!BZ13 -> 317 | BY13: ='[2]Oct-Dec''25'!CA13+'[2]Apr-Sep''25'!CA13 -> 317 | BZ13: =IFERROR(BY13/BX13,0) -> 1 | CA13: ='[2]Oct-Dec''25'!CC13+'[2]Apr-Sep''25'!CC13 -> 42 | CB13: ='[2]Oct-Dec''25'!CD13+'[2]Apr-Sep''25'!CD13 -> 34 | CC13: =IFERROR(CB13/CA13,0) -> 0.80952381 | CD13: ='[2]Oct-Dec''25'!CF13+'[2]Apr-Sep''25'!CF13 -> 0 | CE13: ='[2]Oct-Dec''25'!CG13+'[2]Apr-Sep''25'!CG13 -> 0 | CF13: =IFERROR(CE13/CD13,0) -> 0
A14: ='[2]Oct-Dec''25'!A14 -> 8 | B14: ='[2]Oct-Dec''25'!B14 -> CHRI | C14: ='[2]Oct-Dec''25'!C14 -> Bihar | D14: ='[2]Oct-Dec''25'!D14 -> KNP+ | E14: ='[2]Oct-Dec''25'!E14 -> KATIHAR | F14: Apr-Dec'25 | G14: ='[2]Oct-Dec''25'!H14+'[2]Apr-Sep''25'!H14 -> 623 | H14: ='[2]Oct-Dec''25'!I14+'[2]Apr-Sep''25'!I14 -> 487 | I14: =H14/G14 -> 0.78170144 | J14: ='[2]Oct-Dec''25'!K14+'[2]Apr-Sep''25'!K14 -> 397 | K14: ='[2]Oct-Dec''25'!L14+'[2]Apr-Sep''25'!L14 -> 390 | L14: =K14/J14 -> 0.98236776 | M14: ='[2]Oct-Dec''25'!N14+'[2]Apr-Sep''25'!N14 -> 465 | N14: ='[2]Oct-Dec''25'!O14+'[2]Apr-Sep''25'!O14 -> 465 | O14: =N14/M14 -> 1 | P14: ='[2]Oct-Dec''25'!Q14+'[2]Apr-Sep''25'!Q14 -> 432 | Q14: ='[2]Oct-Dec''25'!R14+'[2]Apr-Sep''25'!R14 -> 332 | R14: =Q14/P14 -> 0.76851852 | S14: ='[2]Oct-Dec''25'!T14+'[2]Apr-Sep''25'!T14 -> 706 | T14: ='[2]Oct-Dec''25'!U14+'[2]Apr-Sep''25'!U14 -> 702 | U14: =T14/S14 -> 0.99433428 | V14: ='[2]Oct-Dec''25'!W14+'[2]Apr-Sep''25'!W14 -> 673 | W14: ='[2]Oct-Dec''25'!Y14+'[2]Apr-Sep''25'!Y14 -> 652 | X14: =W14/V14 -> 0.96879643 | Y14: ='[2]Oct-Dec''25'!AA14+'[2]Apr-Sep''25'!AA14 -> 72 | Z14: ='[2]Oct-Dec''25'!AB14+'[2]Apr-Sep''25'!AB14 -> 72 | AA14: =Z14/Y14 -> 1 | AB14: ='[2]Oct-Dec''25'!AD14+'[2]Apr-Sep''25'!AD14 -> 4 | AC14: ='[2]Oct-Dec''25'!AE14+'[2]Apr-Sep''25'!AE14 -> 4 | AD14: =AC14/AB14 -> 1 | AE14: ='[2]Oct-Dec''25'!AJ14+'[2]Apr-Sep''25'!AJ14 -> 3136 | AF14: ='[2]Oct-Dec''25'!AK14+'[2]Apr-Sep''25'!AK14 -> 3136 | AG14: =AF14/AE14 -> 1 | AH14: ='[2]Oct-Dec''25'!AM14+'[2]Apr-Sep''25'!AM14 -> 0 | AI14: ='[2]Oct-Dec''25'!AN14+'[2]Apr-Sep''25'!AN14 -> 0 | AJ14: =AI14/AH14 -> #DIV/0! | AK14: ='[2]Oct-Dec''25'!AP14+'[2]Apr-Sep''25'!AP14 -> 56 | AL14: ='[2]Oct-Dec''25'!AQ14+'[2]Apr-Sep''25'!AQ14 -> 52 | AM14: =AL14/AK14 -> 0.92857143 | AN14: ='[2]Oct-Dec''25'!AS14+'[2]Apr-Sep''25'!AS14 -> 106 | AO14: ='[2]Oct-Dec''25'!AT14+'[2]Apr-Sep''25'!AT14 -> 106 | AP14: =AO14/AN14 -> 1 | AQ14: ='[2]Oct-Dec''25'!AV14+'[2]Apr-Sep''25'!AV14 -> 0 | AR14: ='[2]Oct-Dec''25'!AW14+'[2]Apr-Sep''25'!AW14 -> 0 | AS14: =AR14/AQ14 -> #DIV/0! | AT14: ='[2]Oct-Dec''25'!AY14+'[2]Apr-Sep''25'!AY14 -> 345 | AU14: ='[2]Oct-Dec''25'!AZ14+'[2]Apr-Sep''25'!AZ14 -> 345 | AV14: =AU14/AT14 -> 1 | AW14: =AN14+AQ14+AT14 -> 451 | AX14: =AO14+AR14+AU14 -> 451 | AY14: =AX14/AW14 -> 1 | AZ14: ='[2]Oct-Dec''25'!BB14+'[2]Apr-Sep''25'!BB14 -> 167 | BA14: ='[2]Oct-Dec''25'!BC14+'[2]Apr-Sep''25'!BC14 -> 167 | BB14: =IFERROR(BA14/AZ14,0) -> 1 | BC14: ='[2]Oct-Dec''25'!BE14+'[2]Apr-Sep''25'!BE14 -> 21 | BD14: ='[2]Oct-Dec''25'!BF14+'[2]Apr-Sep''25'!BF14 -> 21 | BE14: =IFERROR(BD14/BC14,0) -> 1 | BF14: ='[2]Oct-Dec''25'!BH14+'[2]Apr-Sep''25'!BH14 -> 42 | BG14: ='[2]Oct-Dec''25'!BI14+'[2]Apr-Sep''25'!BI14 -> 42 | BH14: =IFERROR(BG14/BF14,0) -> 1 | BI14: ='[2]Oct-Dec''25'!BK14+'[2]Apr-Sep''25'!BK14 -> 26 | BJ14: ='[2]Oct-Dec''25'!BL14+'[2]Apr-Sep''25'!BL14 -> 26 | BK14: =IFERROR(BJ14/BI14,0) -> 1 | BL14: ='[2]Oct-Dec''25'!BN14+'[2]Apr-Sep''25'!BN14 -> 25 | BM14: ='[2]Oct-Dec''25'!BO14+'[2]Apr-Sep''25'!BO14 -> 25 | BN14: =IFERROR(BM14/BL14,0) -> 1 | BO14: ='[2]Oct-Dec''25'!BQ14+'[2]Apr-Sep''25'!BQ14 -> 29 | BP14: ='[2]Oct-Dec''25'!BR14+'[2]Apr-Sep''25'!BR14 -> 27 | BQ14: =IFERROR(BP14/BO14,0) -> 0.93103448 | BR14: ='[2]Oct-Dec''25'!BT14+'[2]Apr-Sep''25'!BT14 -> 46 | BS14: ='[2]Oct-Dec''25'!BU14+'[2]Apr-Sep''25'!BU14 -> 46 | BT14: =IFERROR(BS14/BR14,0) -> 1 | BU14: ='[2]Oct-Dec''25'!BW14+'[2]Apr-Sep''25'!BW14 -> 0 | BV14: ='[2]Oct-Dec''25'!BX14+'[2]Apr-Sep''25'!BX14 -> 0 | BW14: =IFERROR(BV14/BU14,0) -> 0 | BX14: ='[2]Oct-Dec''25'!BZ14+'[2]Apr-Sep''25'!BZ14 -> 487 | BY14: ='[2]Oct-Dec''25'!CA14+'[2]Apr-Sep''25'!CA14 -> 488 | BZ14: =IFERROR(BY14/BX14,0) -> 1.0020534 | CA14: ='[2]Oct-Dec''25'!CC14+'[2]Apr-Sep''25'!CC14 -> 48 | CB14: ='[2]Oct-Dec''25'!CD14+'[2]Apr-Sep''25'!CD14 -> 48 | CC14: =IFERROR(CB14/CA14,0) -> 1 | CD14: ='[2]Oct-Dec''25'!CF14+'[2]Apr-Sep''25'!CF14 -> 0 | CE14: ='[2]Oct-Dec''25'!CG14+'[2]Apr-Sep''25'!CG14 -> 0 | CF14: =IFERROR(CE14/CD14,0) -> 0
A15: ='[2]Oct-Dec''25'!A15 -> 9 | B15: ='[2]Oct-Dec''25'!B15 -> CHRI | C15: ='[2]Oct-Dec''25'!C15 -> Bihar | D15: ='[2]Oct-Dec''25'!D15 -> BNP+ | E15: ='[2]Oct-Dec''25'!E15 -> MADHUBANI | F15: Apr-Dec'25 | G15: ='[2]Oct-Dec''25'!H15+'[2]Apr-Sep''25'!H15 -> 536 | H15: ='[2]Oct-Dec''25'!I15+'[2]Apr-Sep''25'!I15 -> 449 | I15: =H15/G15 -> 0.83768657 | J15: ='[2]Oct-Dec''25'!K15+'[2]Apr-Sep''25'!K15 -> 386 | K15: ='[2]Oct-Dec''25'!L15+'[2]Apr-Sep''25'!L15 -> 386 | L15: =K15/J15 -> 1 | M15: ='[2]Oct-Dec''25'!N15+'[2]Apr-Sep''25'!N15 -> 476 | N15: ='[2]Oct-Dec''25'!O15+'[2]Apr-Sep''25'!O15 -> 476 | O15: =N15/M15 -> 1 | P15: ='[2]Oct-Dec''25'!Q15+'[2]Apr-Sep''25'!Q15 -> 381 | Q15: ='[2]Oct-Dec''25'!R15+'[2]Apr-Sep''25'!R15 -> 365 | R15: =Q15/P15 -> 0.95800525 | S15: ='[2]Oct-Dec''25'!T15+'[2]Apr-Sep''25'!T15 -> 1541 | T15: ='[2]Oct-Dec''25'!U15+'[2]Apr-Sep''25'!U15 -> 1248 | U15: =T15/S15 -> 0.80986372 | V15: ='[2]Oct-Dec''25'!W15+'[2]Apr-Sep''25'!W15 -> 719 | W15: ='[2]Oct-Dec''25'!Y15+'[2]Apr-Sep''25'!Y15 -> 380 | X15: =W15/V15 -> 0.52851182 | Y15: ='[2]Oct-Dec''25'!AA15+'[2]Apr-Sep''25'!AA15 -> 0 | Z15: ='[2]Oct-Dec''25'!AB15+'[2]Apr-Sep''25'!AB15 -> 0 | AA15: =Z15/Y15 -> #DIV/0! | AB15: ='[2]Oct-Dec''25'!AD15+'[2]Apr-Sep''25'!AD15 -> 0 | AC15: ='[2]Oct-Dec''25'!AE15+'[2]Apr-Sep''25'!AE15 -> 0 | AD15: =AC15/AB15 -> #DIV/0! | AE15: ='[2]Oct-Dec''25'!AJ15+'[2]Apr-Sep''25'!AJ15 -> 448 | AF15: ='[2]Oct-Dec''25'!AK15+'[2]Apr-Sep''25'!AK15 -> 417 | AG15: =AF15/AE15 -> 0.93080357 | AH15: ='[2]Oct-Dec''25'!AM15+'[2]Apr-Sep''25'!AM15 -> 0 | AI15: ='[2]Oct-Dec''25'!AN15+'[2]Apr-Sep''25'!AN15 -> 0 | AJ15: =AI15/AH15 -> #DIV/0! | AK15: ='[2]Oct-Dec''25'!AP15+'[2]Apr-Sep''25'!AP15 -> 50 | AL15: ='[2]Oct-Dec''25'!AQ15+'[2]Apr-Sep''25'!AQ15 -> 50 | AM15: =AL15/AK15 -> 1 | AN15: ='[2]Oct-Dec''25'!AS15+'[2]Apr-Sep''25'!AS15 -> 157 | AO15: ='[2]Oct-Dec''25'!AT15+'[2]Apr-Sep''25'!AT15 -> 76 | AP15: =AO15/AN15 -> 0.48407643 | AQ15: ='[2]Oct-Dec''25'!AV15+'[2]Apr-Sep''25'!AV15 -> 135 | AR15: ='[2]Oct-Dec''25'!AW15+'[2]Apr-Sep''25'!AW15 -> 0 | AS15: =AR15/AQ15 -> 0 | AT15: ='[2]Oct-Dec''25'!AY15+'[2]Apr-Sep''25'!AY15 -> 38 | AU15: ='[2]Oct-Dec''25'!AZ15+'[2]Apr-Sep''25'!AZ15 -> 38 | AV15: =AU15/AT15 -> 1 | AW15: =AN15+AQ15+AT15 -> 330 | AX15: =AO15+AR15+AU15 -> 114 | AY15: =AX15/AW15 -> 0.34545455 | AZ15: ='[2]Oct-Dec''25'!BB15+'[2]Apr-Sep''25'!BB15 -> 37 | BA15: ='[2]Oct-Dec''25'!BC15+'[2]Apr-Sep''25'!BC15 -> 36 | BB15: =IFERROR(BA15/AZ15,0) -> 0.97297297 | BC15: ='[2]Oct-Dec''25'!BE15+'[2]Apr-Sep''25'!BE15 -> 16 | BD15: ='[2]Oct-Dec''25'!BF15+'[2]Apr-Sep''25'!BF15 -> 16 | BE15: =IFERROR(BD15/BC15,0) -> 1 | BF15: ='[2]Oct-Dec''25'!BH15+'[2]Apr-Sep''25'!BH15 -> 6 | BG15: ='[2]Oct-Dec''25'!BI15+'[2]Apr-Sep''25'!BI15 -> 6 | BH15: =IFERROR(BG15/BF15,0) -> 1 | BI15: ='[2]Oct-Dec''25'!BK15+'[2]Apr-Sep''25'!BK15 -> 19 | BJ15: ='[2]Oct-Dec''25'!BL15+'[2]Apr-Sep''25'!BL15 -> 22 | BK15: =IFERROR(BJ15/BI15,0) -> 1.1578947 | BL15: ='[2]Oct-Dec''25'!BN15+'[2]Apr-Sep''25'!BN15 -> 18 | BM15: ='[2]Oct-Dec''25'!BO15+'[2]Apr-Sep''25'!BO15 -> 18 | BN15: =IFERROR(BM15/BL15,0) -> 1 | BO15: ='[2]Oct-Dec''25'!BQ15+'[2]Apr-Sep''25'!BQ15 -> 7 | BP15: ='[2]Oct-Dec''25'!BR15+'[2]Apr-Sep''25'!BR15 -> 7 | BQ15: =IFERROR(BP15/BO15,0) -> 1 | BR15: ='[2]Oct-Dec''25'!BT15+'[2]Apr-Sep''25'!BT15 -> 10 | BS15: ='[2]Oct-Dec''25'!BU15+'[2]Apr-Sep''25'!BU15 -> 10 | BT15: =IFERROR(BS15/BR15,0) -> 1 | BU15: ='[2]Oct-Dec''25'!BW15+'[2]Apr-Sep''25'!BW15 -> 1 | BV15: ='[2]Oct-Dec''25'!BX15+'[2]Apr-Sep''25'!BX15 -> 1 | BW15: =IFERROR(BV15/BU15,0) -> 1 | BX15: ='[2]Oct-Dec''25'!BZ15+'[2]Apr-Sep''25'!BZ15 -> 449 | BY15: ='[2]Oct-Dec''25'!CA15+'[2]Apr-Sep''25'!CA15 -> 1335 | BZ15: =IFERROR(BY15/BX15,0) -> 2.9732739 | CA15: ='[2]Oct-Dec''25'!CC15+'[2]Apr-Sep''25'!CC15 -> 61 | CB15: ='[2]Oct-Dec''25'!CD15+'[2]Apr-Sep''25'!CD15 -> 67 | CC15: =IFERROR(CB15/CA15,0) -> 1.0983607 | CD15: ='[2]Oct-Dec''25'!CF15+'[2]Apr-Sep''25'!CF15 -> 0 | CE15: ='[2]Oct-Dec''25'!CG15+'[2]Apr-Sep''25'!CG15 -> 0 | CF15: =IFERROR(CE15/CD15,0) -> 0
A16: ='[2]Oct-Dec''25'!A16 -> 10 | B16: ='[2]Oct-Dec''25'!B16 -> CHRI | C16: ='[2]Oct-Dec''25'!C16 -> Bihar | D16: ='[2]Oct-Dec''25'!D16 -> NIRDESH | E16: ='[2]Oct-Dec''25'!E16 -> EAST CHAMPARAN | F16: Apr-Dec'25 | G16: ='[2]Oct-Dec''25'!H16+'[2]Apr-Sep''25'!H16 -> 919 | H16: ='[2]Oct-Dec''25'!I16+'[2]Apr-Sep''25'!I16 -> 937 | I16: =H16/G16 -> 1.0195865 | J16: ='[2]Oct-Dec''25'!K16+'[2]Apr-Sep''25'!K16 -> 990 | K16: ='[2]Oct-Dec''25'!L16+'[2]Apr-Sep''25'!L16 -> 990 | L16: =K16/J16 -> 1 | M16: ='[2]Oct-Dec''25'!N16+'[2]Apr-Sep''25'!N16 -> 830 | N16: ='[2]Oct-Dec''25'!O16+'[2]Apr-Sep''25'!O16 -> 830 | O16: =N16/M16 -> 1 | P16: ='[2]Oct-Dec''25'!Q16+'[2]Apr-Sep''25'!Q16 -> 710 | Q16: ='[2]Oct-Dec''25'!R16+'[2]Apr-Sep''25'!R16 -> 678 | R16: =Q16/P16 -> 0.95492958 | S16: ='[2]Oct-Dec''25'!T16+'[2]Apr-Sep''25'!T16 -> 4174 | T16: ='[2]Oct-Dec''25'!U16+'[2]Apr-Sep''25'!U16 -> 4104 | U16: =T16/S16 -> 0.98322952 | V16: ='[2]Oct-Dec''25'!W16+'[2]Apr-Sep''25'!W16 -> 491 | W16: ='[2]Oct-Dec''25'!Y16+'[2]Apr-Sep''25'!Y16 -> 457 | X16: =W16/V16 -> 0.93075356 | Y16: ='[2]Oct-Dec''25'!AA16+'[2]Apr-Sep''25'!AA16 -> 0 | Z16: ='[2]Oct-Dec''25'!AB16+'[2]Apr-Sep''25'!AB16 -> 0 | AA16: =Z16/Y16 -> #DIV/0! | AB16: ='[2]Oct-Dec''25'!AD16+'[2]Apr-Sep''25'!AD16 -> 0 | AC16: ='[2]Oct-Dec''25'!AE16+'[2]Apr-Sep''25'!AE16 -> 0 | AD16: =AC16/AB16 -> #DIV/0! | AE16: ='[2]Oct-Dec''25'!AJ16+'[2]Apr-Sep''25'!AJ16 -> 3746 | AF16: ='[2]Oct-Dec''25'!AK16+'[2]Apr-Sep''25'!AK16 -> 3746 | AG16: =AF16/AE16 -> 1 | AH16: ='[2]Oct-Dec''25'!AM16+'[2]Apr-Sep''25'!AM16 -> 0 | AI16: ='[2]Oct-Dec''25'!AN16+'[2]Apr-Sep''25'!AN16 -> 0 | AJ16: =AI16/AH16 -> #DIV/0! | AK16: ='[2]Oct-Dec''25'!AP16+'[2]Apr-Sep''25'!AP16 -> 110 | AL16: ='[2]Oct-Dec''25'!AQ16+'[2]Apr-Sep''25'!AQ16 -> 110 | AM16: =AL16/AK16 -> 1 | AN16: ='[2]Oct-Dec''25'!AS16+'[2]Apr-Sep''25'!AS16 -> 518 | AO16: ='[2]Oct-Dec''25'!AT16+'[2]Apr-Sep''25'!AT16 -> 518 | AP16: =AO16/AN16 -> 1 | AQ16: ='[2]Oct-Dec''25'!AV16+'[2]Apr-Sep''25'!AV16 -> 0 | AR16: ='[2]Oct-Dec''25'!AW16+'[2]Apr-Sep''25'!AW16 -> 0 | AS16: =AR16/AQ16 -> #DIV/0! | AT16: ='[2]Oct-Dec''25'!AY16+'[2]Apr-Sep''25'!AY16 -> 832 | AU16: ='[2]Oct-Dec''25'!AZ16+'[2]Apr-Sep''25'!AZ16 -> 806 | AV16: =AU16/AT16 -> 0.96875 | AW16: =AN16+AQ16+AT16 -> 1350 | AX16: =AO16+AR16+AU16 -> 1324 | AY16: =AX16/AW16 -> 0.98074074 | AZ16: ='[2]Oct-Dec''25'!BB16+'[2]Apr-Sep''25'!BB16 -> 237 | BA16: ='[2]Oct-Dec''25'!BC16+'[2]Apr-Sep''25'!BC16 -> 237 | BB16: =IFERROR(BA16/AZ16,0) -> 1 | BC16: ='[2]Oct-Dec''25'!BE16+'[2]Apr-Sep''25'!BE16 -> 35 | BD16: ='[2]Oct-Dec''25'!BF16+'[2]Apr-Sep''25'!BF16 -> 35 | BE16: =IFERROR(BD16/BC16,0) -> 1 | BF16: ='[2]Oct-Dec''25'!BH16+'[2]Apr-Sep''25'!BH16 -> 31 | BG16: ='[2]Oct-Dec''25'!BI16+'[2]Apr-Sep''25'!BI16 -> 31 | BH16: =IFERROR(BG16/BF16,0) -> 1 | BI16: ='[2]Oct-Dec''25'!BK16+'[2]Apr-Sep''25'!BK16 -> 53 | BJ16: ='[2]Oct-Dec''25'!BL16+'[2]Apr-Sep''25'!BL16 -> 53 | BK16: =IFERROR(BJ16/BI16,0) -> 1 | BL16: ='[2]Oct-Dec''25'!BN16+'[2]Apr-Sep''25'!BN16 -> 21 | BM16: ='[2]Oct-Dec''25'!BO16+'[2]Apr-Sep''25'!BO16 -> 21 | BN16: =IFERROR(BM16/BL16,0) -> 1 | BO16: ='[2]Oct-Dec''25'!BQ16+'[2]Apr-Sep''25'!BQ16 -> 17 | BP16: ='[2]Oct-Dec''25'!BR16+'[2]Apr-Sep''25'!BR16 -> 17 | BQ16: =IFERROR(BP16/BO16,0) -> 1 | BR16: ='[2]Oct-Dec''25'!BT16+'[2]Apr-Sep''25'!BT16 -> 53 | BS16: ='[2]Oct-Dec''25'!BU16+'[2]Apr-Sep''25'!BU16 -> 46 | BT16: =IFERROR(BS16/BR16,0) -> 0.86792453 | BU16: ='[2]Oct-Dec''25'!BW16+'[2]Apr-Sep''25'!BW16 -> 0 | BV16: ='[2]Oct-Dec''25'!BX16+'[2]Apr-Sep''25'!BX16 -> 0 | BW16: =IFERROR(BV16/BU16,0) -> 0 | BX16: ='[2]Oct-Dec''25'!BZ16+'[2]Apr-Sep''25'!BZ16 -> 937 | BY16: ='[2]Oct-Dec''25'!CA16+'[2]Apr-Sep''25'!CA16 -> 927 | BZ16: =IFERROR(BY16/BX16,0) -> 0.98932764 | CA16: ='[2]Oct-Dec''25'!CC16+'[2]Apr-Sep''25'!CC16 -> 92 | CB16: ='[2]Oct-Dec''25'!CD16+'[2]Apr-Sep''25'!CD16 -> 92 | CC16: =IFERROR(CB16/CA16,0) -> 1 | CD16: ='[2]Oct-Dec''25'!CF16+'[2]Apr-Sep''25'!CF16 -> 6 | CE16: ='[2]Oct-Dec''25'!CG16+'[2]Apr-Sep''25'!CG16 -> 6 | CF16: =IFERROR(CE16/CD16,0) -> 1
A17: ='[2]Oct-Dec''25'!A17 -> 11 | B17: ='[2]Oct-Dec''25'!B17 -> CHRI | C17: ='[2]Oct-Dec''25'!C17 -> Bihar | D17: ='[2]Oct-Dec''25'!D17 -> BNP+ | E17: ='[2]Oct-Dec''25'!E17 -> MUZAFFARPUR | F17: Apr-Dec'25 | G17: ='[2]Oct-Dec''25'!H17+'[2]Apr-Sep''25'!H17 -> 386 | H17: ='[2]Oct-Dec''25'!I17+'[2]Apr-Sep''25'!I17 -> 369 | I17: =H17/G17 -> 0.95595855 | J17: ='[2]Oct-Dec''25'!K17+'[2]Apr-Sep''25'!K17 -> 335 | K17: ='[2]Oct-Dec''25'!L17+'[2]Apr-Sep''25'!L17 -> 321 | L17: =K17/J17 -> 0.95820896 | M17: ='[2]Oct-Dec''25'!N17+'[2]Apr-Sep''25'!N17 -> 346 | N17: ='[2]Oct-Dec''25'!O17+'[2]Apr-Sep''25'!O17 -> 344 | O17: =N17/M17 -> 0.99421965 | P17: ='[2]Oct-Dec''25'!Q17+'[2]Apr-Sep''25'!Q17 -> 357 | Q17: ='[2]Oct-Dec''25'!R17+'[2]Apr-Sep''25'!R17 -> 331 | R17: =Q17/P17 -> 0.92717087 | S17: ='[2]Oct-Dec''25'!T17+'[2]Apr-Sep''25'!T17 -> 2674 | T17: ='[2]Oct-Dec''25'!U17+'[2]Apr-Sep''25'!U17 -> 2485 | U17: =T17/S17 -> 0.92931937 | V17: ='[2]Oct-Dec''25'!W17+'[2]Apr-Sep''25'!W17 -> 336 | W17: ='[2]Oct-Dec''25'!Y17+'[2]Apr-Sep''25'!Y17 -> 220 | X17: =W17/V17 -> 0.6547619 | Y17: ='[2]Oct-Dec''25'!AA17+'[2]Apr-Sep''25'!AA17 -> 148 | Z17: ='[2]Oct-Dec''25'!AB17+'[2]Apr-Sep''25'!AB17 -> 148 | AA17: =Z17/Y17 -> 1 | AB17: ='[2]Oct-Dec''25'!AD17+'[2]Apr-Sep''25'!AD17 -> 145 | AC17: ='[2]Oct-Dec''25'!AE17+'[2]Apr-Sep''25'!AE17 -> 44 | AD17: =AC17/AB17 -> 0.30344828 | AE17: ='[2]Oct-Dec''25'!AJ17+'[2]Apr-Sep''25'!AJ17 -> 703 | AF17: ='[2]Oct-Dec''25'!AK17+'[2]Apr-Sep''25'!AK17 -> 404 | AG17: =AF17/AE17 -> 0.57467994 | AH17: ='[2]Oct-Dec''25'!AM17+'[2]Apr-Sep''25'!AM17 -> 0 | AI17: ='[2]Oct-Dec''25'!AN17+'[2]Apr-Sep''25'!AN17 -> 0 | AJ17: =AI17/AH17 -> #DIV/0! | AK17: ='[2]Oct-Dec''25'!AP17+'[2]Apr-Sep''25'!AP17 -> 227 | AL17: ='[2]Oct-Dec''25'!AQ17+'[2]Apr-Sep''25'!AQ17 -> 93 | AM17: =AL17/AK17 -> 0.40969163 | AN17: ='[2]Oct-Dec''25'!AS17+'[2]Apr-Sep''25'!AS17 -> 72 | AO17: ='[2]Oct-Dec''25'!AT17+'[2]Apr-Sep''25'!AT17 -> 72 | AP17: =AO17/AN17 -> 1 | AQ17: ='[2]Oct-Dec''25'!AV17+'[2]Apr-Sep''25'!AV17 -> 0 | AR17: ='[2]Oct-Dec''25'!AW17+'[2]Apr-Sep''25'!AW17 -> 0 | AS17: =AR17/AQ17 -> #DIV/0! | AT17: ='[2]Oct-Dec''25'!AY17+'[2]Apr-Sep''25'!AY17 -> 71 | AU17: ='[2]Oct-Dec''25'!AZ17+'[2]Apr-Sep''25'!AZ17 -> 71 | AV17: =AU17/AT17 -> 1 | AW17: =AN17+AQ17+AT17 -> 143 | AX17: =AO17+AR17+AU17 -> 143 | AY17: =AX17/AW17 -> 1 | AZ17: ='[2]Oct-Dec''25'!BB17+'[2]Apr-Sep''25'!BB17 -> 162 | BA17: ='[2]Oct-Dec''25'!BC17+'[2]Apr-Sep''25'!BC17 -> 162 | BB17: =IFERROR(BA17/AZ17,0) -> 1 | BC17: ='[2]Oct-Dec''25'!BE17+'[2]Apr-Sep''25'!BE17 -> 19 | BD17: ='[2]Oct-Dec''25'!BF17+'[2]Apr-Sep''25'!BF17 -> 19 | BE17: =IFERROR(BD17/BC17,0) -> 1 | BF17: ='[2]Oct-Dec''25'!BH17+'[2]Apr-Sep''25'!BH17 -> 33 | BG17: ='[2]Oct-Dec''25'!BI17+'[2]Apr-Sep''25'!BI17 -> 32 | BH17: =IFERROR(BG17/BF17,0) -> 0.96969697 | BI17: ='[2]Oct-Dec''25'!BK17+'[2]Apr-Sep''25'!BK17 -> 46 | BJ17: ='[2]Oct-Dec''25'!BL17+'[2]Apr-Sep''25'!BL17 -> 46 | BK17: =IFERROR(BJ17/BI17,0) -> 1 | BL17: ='[2]Oct-Dec''25'!BN17+'[2]Apr-Sep''25'!BN17 -> 29 | BM17: ='[2]Oct-Dec''25'!BO17+'[2]Apr-Sep''25'!BO17 -> 29 | BN17: =IFERROR(BM17/BL17,0) -> 1 | BO17: ='[2]Oct-Dec''25'!BQ17+'[2]Apr-Sep''25'!BQ17 -> 20 | BP17: ='[2]Oct-Dec''25'!BR17+'[2]Apr-Sep''25'!BR17 -> 20 | BQ17: =IFERROR(BP17/BO17,0) -> 1 | BR17: ='[2]Oct-Dec''25'!BT17+'[2]Apr-Sep''25'!BT17 -> 29 | BS17: ='[2]Oct-Dec''25'!BU17+'[2]Apr-Sep''25'!BU17 -> 29 | BT17: =IFERROR(BS17/BR17,0) -> 1 | BU17: ='[2]Oct-Dec''25'!BW17+'[2]Apr-Sep''25'!BW17 -> 1 | BV17: ='[2]Oct-Dec''25'!BX17+'[2]Apr-Sep''25'!BX17 -> 1 | BW17: =IFERROR(BV17/BU17,0) -> 1 | BX17: ='[2]Oct-Dec''25'!BZ17+'[2]Apr-Sep''25'!BZ17 -> 369 | BY17: ='[2]Oct-Dec''25'!CA17+'[2]Apr-Sep''25'!CA17 -> 385 | BZ17: =IFERROR(BY17/BX17,0) -> 1.0433604 | CA17: ='[2]Oct-Dec''25'!CC17+'[2]Apr-Sep''25'!CC17 -> 38 | CB17: ='[2]Oct-Dec''25'!CD17+'[2]Apr-Sep''25'!CD17 -> 23 | CC17: =IFERROR(CB17/CA17,0) -> 0.60526316 | CD17: ='[2]Oct-Dec''25'!CF17+'[2]Apr-Sep''25'!CF17 -> 0 | CE17: ='[2]Oct-Dec''25'!CG17+'[2]Apr-Sep''25'!CG17 -> 0 | CF17: =IFERROR(CE17/CD17,0) -> 0
